Workbook
Name dateColumn_Reminder_1612459588747: Customers!$J$1

Sheet Main
A1: Product Code | B1: Category | C1: Sub Category | D1: Specifications | E1: No. of Ups | F1: Machine | G1: Flexible Machine | H1: Sheet W | I1: Sheet H | J1: GSM | K1: Final Qty | L1: Sheet Qty | M1: Work and Tumble | N1: Digital Qty | P1: SBS | U1: Other Type | V1: Designing | W1: Silver Foiling | X1: Printing | Y1: Flexible Print | Z1: Die | AA1: Leafing / Embossing | AB1: Window | AC1: Pasting | AD1: Other Charges | AE1: Total | AF1: Total Qty | AG1: SBS | AH1: WhiteBack | AI1: GreyBack | AJ1: Art Card | AK1: Maplitho | AL1: Other Type | AM1: Custom Paper | AW1: Lamination Thermal | AX1: Lamination Normal Gloss | AY1: Lamination Normal Matt | AZ1: Varnish | BA1: UV Flat | BB1: UV Crystal | BC1: UV Hybrid | BD1: Spot UV | BG1: Height | BH1: Length | BI1: Gumming Full | BJ1: Gumming Top Bottom | BK1: Gumming 4 Sides | BL1: Dangle Making | BM1: Dangle With Rivet | BN1: Dangler With Rivet and Elastic | BO1: Half Cut Front | BP1: Half Cut Back | BQ1: Cutting | BR1: Custom Gumming | BS1: Carry Bag Single Pasting | BT1: Carry Bag Double Pasting | BU1: Leafing
A2: =Sheet2!A2 -> https://drive.google.com/open?id=1NLrZ9Hf7XX7ORpYJXuBzVfkGVvuPoBZu&authuser=jay.agg%40gmail.com&usp=drive_fs | B2: =Sheet2!B2 -> Bakery | C2: =Sheet2!C2 -> Brownie 2 | D2: =Sheet2!D2 -> 180*70*35 mm | 7*2.75*1.4 inch | E2: =Max(Sheet2!E2,Sheet2!E4) -> 4 | F2: =Product!CF155 -> 2029 | G2: =Product!BI45 -> 1926 | H2: =Max(Sheet2!G2,Sheet2!G4) -> 19 | I2: =Max(Sheet2!H2,Sheet2!H4) -> 20 | J2: =L5 -> 280 | K2: =IFNA(Product!H2,"") -> 10 | L2: =ROUNDUP((K2/E2)+80,0) -> 83 | M2: =ROUNDUP(((K2/E2)*Sheet2!$AB$5)+80,0) -> 83 | N2: =Roundup((K2/E2),0) -> 3 | P2: =(Roundup((((((H2*I2)/1550)*(J2/1000))*(Product!$CC$5+2))*L2)+((L2/144)*15),0)) -> 21 | U2: =Roundup(((((Product!$BZ$5+1))*L2)+((L2/144)*10)),0) -> 7144 | V2: 100 | W2: =Roundup(F5*I2*M2*Sheet2!E79*Sheet2!E71,0) -> 0 | X2: =IFNA((IFS(F2=1926,LOOKUP(M2,(Price!$AA$1:$AB$300),(Price!$AC$1:$AC$300)),F2=2029,LOOKUP(M2,(Price!$AA$1:$AB$300),(Price!$AF$1:$AF$300)),F2=3001,LOOKUP(N2,(Price!$AI$2:$AJ$8),(Price!$AK$2:$AK$8)),F2=2030,LOOKUP(M2,(Price!$AA$1:$AB$300),(Price!$BE$1:$BE$300)),F2=2841,LOOKUP(M2,(Price!$AA$1:$AB$300),(Price!$BF$1:$BF$300)),F2=2840,LOOKUP(M2,(Price!$AA$1:$AB$300),(Price!$AG$1:$AG$300)))),"")*Product!$BB$15+$AH$5+W2 -> 575 | Y2: =IFNA(IFS(G2=1002,LOOKUP(O2,(Price!$AI$2:$AJ$8),(Price!$AL$2:$AL$8)),G2=1003,lookup(O2,(Price!$AI$2:$AJ$8),(Price!$AM$2:$AM$8)),G2=1004,lookup(O2,(Price!$AI$2:$AJ$8),(Price!$AN$2:$AN$8))),"")*Product!$BB$15 -> 0 | Z2: =(LOOKUP(L2,(Price!$AA$2:$AB$300),(Price!$AD$2:$AD$300)))*Sheet2!Z11 -> 300 | AA2: =Sheet2!K2 | AB2: =Sheet2!L2 -> 1 | AC2: =Sheet2!M2 | AD2: =ROUNDUP(((K2*AB2)+((K2*AB2)*5%))+(Max(((L2*E2)*AC2),200)+1),0) -> 212 | AE2: =ROUNDUP(V2+Z2+AA2+AB2+AC2,0) -> 401 | AF2: =K2 -> 10 | AG2: =(((((P2+AE2+X2+AD2)/AF2))*(0))+((P2+AE2+X2+AD2)/AF2))+$AG$5 -> 120.9 | AL2: =(((((U2+AE2+X2+AD2)/AF2)*(0))+((U2+AE2+X2+AD2)/AF2)))+$AJ$5 -> 833.2 | AM2: =((((((Roundup((((((AL$5*AM$5)/1550)*(J2/1000))*(Product!$CC$5+2))*L2)+((L2/144)*15),0))+AE2+X2+AD2)/AF2))*(0))+(((Roundup((((((AL$5*AM$5)/1550)*(J2/1000))*(Product!$CC$5+2))*L2)+((L2/144)*15),0))+AE2+X2+AD2)/AF2))+$AG$5 -> 119.7 | AW2: =MAX((((H2*I2)*(Price!$T$2)*L2)/AF2),300/AF2) -> 30 | AX2: =MAX((((H2*I2)*(Price!$S$2)*L2)/AF2),300/AF2) -> 30 | AY2: =MAX((((H2*I2)*(Price!$S$3)*L2)/AF2),300/AF2) -> 30 | AZ2: =MAX((((H2*I2)*(Price!$V$2)*L2)/AF2),300/AF2) -> 30 | BA2: =MAX(((((H2*I2)*(Price!$W$2)*L2)/AF2)+(350/AF2)),500/AF2) -> 50 | BB2: =MAX(((((H2*I2)*(Price!$Y$7)*L2)/AF2)+(350/AF2)),2500/AF2)+AW2 -> 280 | BC2: =MAX(((((H2*I2)*(Price!$U$2)*L2)/AF2)+(350/AF2)),2500/AF2) -> 250 | BD2: =(MAX(BE2:BF2)) -> 175 | BE2: =(MAX((((((((Price!$X$2)*0.17)+(Price!$X$2))*L2)+(350))/AF2)+AW2),500/AF2)) -> 74.711 | BF2: =((((Price!$Y$2)+350)/AF2)+AW2) -> 175 | BG2: =IFERROR(__xludf.DUMMYFUNCTION("(SPLIT(Quotation!$D$22,""*""))"),"#VALUE!") -> #VALUE! | BI2: =(Max(((((((H2*I2)*Price!$R$7)*L2)/AF2)*0)+((((H2*I2)*Price!$R$7)*L2)/AF2)+BQ2),500/AF2)) -> 50 | BJ2: =(MAX((((BG2*2)*Price!$S$7)+(((BG2*2)*Price!$S$7)*0)+BQ2),500/AF2)) -> #VALUE! | BK2: =(MAX(((((BG2*2)+(BH2*2))*Price!$S$7)+((((BG2*2)+(BH2*2))*Price!$S$7)*0)+BQ2),500/AF2)) -> #VALUE! | BL2: =(MAX((((LOOKUP(K2,(Price!$AA$2:$AB$1199),(Price!$AE$2:$AE$1199)))+((LOOKUP(K2,(Price!$AA$2:$AB$1199),(Price!$AE$2:$AE$1199)))*0))+BQ2),500/AF2)) -> 50 | BM2: =(MAX(((((Price!$U$7)+((Price!$U$7)*0))/K2)+BL2),500/AF2)) -> 55 | BN2: =(MAX(((((Price!$V$7)+((Price!$V$7)*0))/K2)+BL2),500/AF2)) -> 60 | BO2: =(((MAX((($BO$5*L2)),300))/E2)/L2) -> 0.90361446 | BP2: =(((MAX((($BP$5*L2)),300))/E2)/L2) -> 0.90361446 | BQ2: =(((MAX((($BQ$5*L2)),300))/L2)/E2) -> 0.90361446 | BR2: =((((MAX((((($BI$5*$BJ$5)*Price!$S$7)*L2)),300))/E2)/L2)+((((MAX((((($BI$5*$BJ$5)*Price!$S$7)*L2)),300))/E2)/L2)*Sheet2!Z33)) -> #VALUE! | BS2: =((MAX((K2*Price!$U$12),300))/K2) -> 30 | BT2: =((MAX((K2*Price!$V$12),300))/K2) -> 30 | BU2: =(iferror(roundup((((MAX((L2*E2*BR5*BS$5*BT$5*Price!Z21),1500))+(BR5*BS5*BT5*E2*Price!Y21)))+((((MAX((L2*E2*BR5*BS$5*BT$5*Price!Z21),1500))+(BR5*BS5*BT5*E2*Price!Y21)))*Sheet2!Z33),0),""))*Product!CF87 -> 0
A3: =A2 -> https://drive.google.com/open?id=1NLrZ9Hf7XX7ORpYJXuBzVfkGVvuPoBZu&authuser=jay.agg%40gmail.com&usp=drive_fs | B3: =B2 -> Bakery | C3: =C2 -> Brownie 2 | D3: =D2 -> 180*70*35 mm | 7*2.75*1.4 inch | E3: =E2 -> 4 | F3: =F2 -> 2029 | G3: =G2 -> 1926 | H3: =H2 -> 19 | ... J3: =J2 -> 280 | K3: =IFNA(Product!H4,"") -> 90 | L3: =ROUNDUP((K3/E3)+80,0) -> 103 | M3: =ROUNDUP(((K3/E3)*Sheet2!$AB$5)+80,0) -> 103 | N3: =Roundup((K3/E3),0) -> 23 | P3: =(Roundup((((((H3*I3)/1550)*(J3/1000))*(Product!$CC$5+2))*L3)+((L3/144)*15),0)) -> 25 | U3: =Roundup(((((Product!$BZ$5+1))*L3)+((L3/144)*10)),0) -> 8866 | V3: =V2 -> 100 | W3: =Roundup(F5*I2*M3*Sheet2!E79*Sheet2!E71,0) -> 0 | X3: =IFNA((IFS(F3=1926,LOOKUP(M3,(Price!$AA$1:$AB$300),(Price!$AC$1:$AC$300)),F3=2029,LOOKUP(M3,(Price!$AA$1:$AB$300),(Price!$AF$1:$AF$300)),F3=3001,LOOKUP(N3,(Price!$AI$2:$AJ$8),(Price!$AK$2:$AK$8)),F3=2030,LOOKUP(M3,(Price!$AA$1:$AB$300),(Price!$BE$1:$BE$300)),F3=2841,LOOKUP(M3,(Price!$AA$1:$AB$300),(Price!$BF$1:$BF$300)),F3=2840,LOOKUP(M3,(Price!$AA$1:$AB$300),(Price!$AG$1:$AG$300)))),"")*Product!$BB$15+$AH$5+W3 -> 575 | Y3: =IFNA(IFS(G3=1002,LOOKUP(O3,(Price!$AI$2:$AJ$8),(Price!$AL$2:$AL$8)),G3=1003,lookup(O3,(Price!$AI$2:$AJ$8),(Price!$AM$2:$AM$8)),G3=1004,lookup(O3,(Price!$AI$2:$AJ$8),(Price!$AN$2:$AN$8))),"")*Product!$BB$15 -> 0 | Z3: =(LOOKUP(L3,(Price!$AA$2:$AB$300),(Price!$AD$2:$AD$300)))*Sheet2!Z11 -> 300 | AA3: =AA2 | AB3: =AB2 -> 1 | AC3: =AC2 | AD3: =ROUNDUP(((K3*AB3)+((K3*AB3)*5%))+(Max(((L3*E3)*AC3),200)+1),0) -> 296 | AE3: =ROUNDUP(V3+Z3+AA3+AB3+AC3,0) -> 401 | AF3: =K3 -> 90 | AG3: =(((((P3+AE3+X3+AD3)/AF3))*(0))+((P3+AE3+X3+AD3)/AF3))+$AG$5 -> 14.411111 | AL3: =(((((U3+AE3+X3+AD3)/AF3)*(0))+((U3+AE3+X3+AD3)/AF3)))+$AJ$5 -> 112.64444 | AM3: =((((((Roundup((((((AL$5*AM$5)/1550)*(J3/1000))*(Product!$CC$5+2))*L3)+((L3/144)*15),0))+AE3+X3+AD3)/AF3))*(0))+(((Roundup((((((AL$5*AM$5)/1550)*(J3/1000))*(Product!$CC$5+2))*L3)+((L3/144)*15),0))+AE3+X3+AD3)/AF3))+$AG$5 -> 14.255556 | AW3: =MAX((((H3*I3)*(Price!$T$2)*L3)/AF3),300/AF3) -> 3.4791111 | AX3: =MAX((((H3*I3)*(Price!$S$2)*L3)/AF3),300/AF3) -> 3.3333333 | AY3: =MAX((((H3*I3)*(Price!$S$3)*L3)/AF3),300/AF3) -> 3.3333333 | AZ3: =MAX((((H3*I3)*(Price!$V$2)*L3)/AF3),300/AF3) -> 3.3333333 | BA3: =MAX(((((H3*I3)*(Price!$W$2)*L3)/AF3)+(350/AF3)),500/AF3) -> 5.5555556 | BB3: =MAX(((((H3*I3)*(Price!$Y$7)*L3)/AF3)+(350/AF3)),2500/AF3)+AW3 -> 31.256889 | BC3: =MAX(((((H3*I3)*(Price!$U$2)*L3)/AF3)+(350/AF3)),2500/AF3) -> 27.777778 | BD3: =(MAX(BE3:BF3)) -> 19.590222 | BE3: =(MAX((((((((Price!$X$2)*0.17)+(Price!$X$2))*L3)+(350))/AF3)+AW3),500/AF3)) -> 8.707 | BF3: =((((Price!$Y$2)+350)/AF3)+AW3) -> 19.590222 | BG3: =IFERROR(__xludf.DUMMYFUNCTION("(SPLIT(Quotation!$D$22,""*""))"),"#VALUE!") -> #VALUE! | BI3: =(Max(((((((H3*I3)*Price!$R$7)*L3)/AF3)*0)+((((H3*I3)*Price!$R$7)*L3)/AF3)+BQ3),500/AF3)) -> 6.1642665 | BJ3: =(MAX((((BG3*2)*Price!$S$7)+(((BG3*2)*Price!$S$7)*0)+BQ3),500/AF3)) -> #VALUE! | BK3: =(MAX(((((BG3*2)+(BH3*2))*Price!$S$7)+((((BG3*2)+(BH3*2))*Price!$S$7)*0)+BQ3),500/AF3)) -> #VALUE! | BL3: =(MAX((((LOOKUP(K3,(Price!$AA$2:$AB$1199),(Price!$AE$2:$AE$1199)))+((LOOKUP(K3,(Price!$AA$2:$AB$1199),(Price!$AE$2:$AE$1199)))*0))+BQ3),500/AF3)) -> 5.5555556 | BM3: =(MAX(((((Price!$U$7)+((Price!$U$7)*0))/K3)+BL3),500/AF3)) -> 6.1111111 | BN3: =(MAX(((((Price!$V$7)+((Price!$V$7)*0))/K3)+BL3),500/AF3)) -> 6.6666667 | BO3: =(((MAX((($BO$5*L3)),300))/E3)/L3) -> 0.72815534 | BP3: =(((MAX((($BP$5*L3)),300))/E3)/L3) -> 0.72815534 | BQ3: =(((MAX((($BQ$5*L3)),300))/L3)/E3) -> 0.72815534 | BR3: =((((MAX((((($BI$5*$BJ$5)*Price!$S$7)*L3)),300))/E3)/L3)+((((MAX((((($BI$5*$BJ$5)*Price!$S$7)*L3)),300))/E3)/L3)*Sheet2!Z34)) -> #VALUE! | BS3: =((MAX((K3*Price!$U$12),300))/K3) -> 5 | BT3: =((MAX((K3*Price!$V$12),300))/K3) -> 6
A4: =A2 -> https://drive.google.com/open?id=1NLrZ9Hf7XX7ORpYJXuBzVfkGVvuPoBZu&authuser=jay.agg%40gmail.com&usp=drive_fs | B4: =B2 -> Bakery | C4: =C2 -> Brownie 2 | D4: =D2 -> 180*70*35 mm | 7*2.75*1.4 inch | E4: =E2 -> 4 | F4: =F2 -> 2029 | G4: =G2 -> 1926 | H4: =H2 -> 19 | ... J4: =J2 -> 280 | K4: =IFNA(Product!H6,"") -> 100 | L4: =ROUNDUP((K4/E4)+80,0) -> 105 | M4: =ROUNDUP(((K4/E4)*Sheet2!$AB$5)+80,0) -> 105 | N4: =Roundup((K4/E4),0) -> 25 | P4: =(Roundup((((((H4*I4)/1550)*(J4/1000))*(Product!$CC$5+2))*L4)+((L4/144)*15),0)) -> 26 | U4: =Roundup(((((Product!$BZ$5+1))*L4)+((L4/144)*10)),0) -> 9038 | V4: =V2 -> 100 | W4: =Roundup(F5*I2*M4*Sheet2!E79*Sheet2!E71,0) -> 0 | X4: =IFNA((IFS(F4=1926,LOOKUP(M4,(Price!$AA$1:$AB$300),(Price!$AC$1:$AC$300)),F4=2029,LOOKUP(M4,(Price!$AA$1:$AB$300),(Price!$AF$1:$AF$300)),F4=3001,LOOKUP(N4,(Price!$AI$2:$AJ$8),(Price!$AK$2:$AK$8)),F4=2030,LOOKUP(M4,(Price!$AA$1:$AB$300),(Price!$BE$1:$BE$300)),F4=2841,LOOKUP(M4,(Price!$AA$1:$AB$300),(Price!$BF$1:$BF$300)),F4=2840,LOOKUP(M4,(Price!$AA$1:$AB$300),(Price!$AG$1:$AG$300)))),"")*Product!$BB$15+$AH$5+W4 -> 575 | Y4: =IFNA(IFS(G4=1002,LOOKUP(O4,(Price!$AI$2:$AJ$8),(Price!$AL$2:$AL$8)),G4=1003,lookup(O4,(Price!$AI$2:$AJ$8),(Price!$AM$2:$AM$8)),G4=1004,lookup(O4,(Price!$AI$2:$AJ$8),(Price!$AN$2:$AN$8))),"")*Product!$BB$15 -> 0 | Z4: =(LOOKUP(L4,(Price!$AA$2:$AB$300),(Price!$AD$2:$AD$300)))*Sheet2!Z11 -> 300 | AA4: =AA2 | AB4: =AB2 -> 1 | AC4: =AC2 | AD4: =ROUNDUP(((K4*AB4)+((K4*AB4)*5%))+(Max(((L4*E4)*AC4),200)+1),0) -> 306 | AE4: =ROUNDUP(V4+Z4+AA4+AB4+AC4,0) -> 401 | AF4: =K4 -> 100 | AG4: =(((((P4+AE4+X4+AD4)/AF4))*(0))+((P4+AE4+X4+AD4)/AF4))+$AG$5 -> 13.08 | AL4: =(((((U4+AE4+X4+AD4)/AF4)*(0))+((U4+AE4+X4+AD4)/AF4)))+$AJ$5 -> 103.2 | AM4: =((((((Roundup((((((AL$5*AM$5)/1550)*(J4/1000))*(Product!$CC$5+2))*L4)+((L4/144)*15),0))+AE4+X4+AD4)/AF4))*(0))+(((Roundup((((((AL$5*AM$5)/1550)*(J4/1000))*(Product!$CC$5+2))*L4)+((L4/144)*15),0))+AE4+X4+AD4)/AF4))+$AG$5 -> 12.93 | AW4: =MAX((((H4*I4)*(Price!$T$2)*L4)/AF4),300/AF4) -> 3.192 | AX4: =MAX((((H4*I4)*(Price!$S$2)*L4)/AF4),300/AF4) -> 3 | AY4: =MAX((((H4*I4)*(Price!$S$3)*L4)/AF4),300/AF4) -> 3 | AZ4: =MAX((((H4*I4)*(Price!$V$2)*L4)/AF4),300/AF4) -> 3 | BA4: =MAX(((((H4*I4)*(Price!$W$2)*L4)/AF4)+(350/AF4)),500/AF4) -> 5 | BB4: =MAX(((((H4*I4)*(Price!$Y$7)*L4)/AF4)+(350/AF4)),2500/AF4)+AW4 -> 28.192 | BC4: =MAX(((((H4*I4)*(Price!$U$2)*L4)/AF4)+(350/AF4)),2500/AF4) -> 25 | BD4: =(MAX(BE4:BF4)) -> 17.692 | BE4: =(MAX((((((((Price!$X$2)*0.17)+(Price!$X$2))*L4)+(350))/AF4)+AW4),500/AF4)) -> 7.9205 | BF4: =((((Price!$Y$2)+350)/AF4)+AW4) -> 17.692 | BG4: =IFERROR(__xludf.DUMMYFUNCTION("(SPLIT(Quotation!$D$22,""*""))"),"#VALUE!") -> #VALUE! | BI4: =(Max(((((((H4*I4)*Price!$R$7)*L4)/AF4)*0)+((((H4*I4)*Price!$R$7)*L4)/AF4)+BQ4),500/AF4)) -> 5.7017857 | BJ4: =(MAX((((BG4*2)*Price!$S$7)+(((BG4*2)*Price!$S$7)*0)+BQ4),500/AF4)) -> #VALUE! | BK4: =(MAX(((((BG4*2)+(BH4*2))*Price!$S$7)+((((BG4*2)+(BH4*2))*Price!$S$7)*0)+BQ4),500/AF4)) -> #VALUE! | BL4: =(MAX((((LOOKUP(K4,(Price!$AA$2:$AB$1199),(Price!$AE$2:$AE$1199)))+((LOOKUP(K4,(Price!$AA$2:$AB$1199),(Price!$AE$2:$AE$1199)))*0))+BQ4),500/AF4)) -> 5 | BM4: =(MAX(((((Price!$U$7)+((Price!$U$7)*0))/K4)+BL4),500/AF4)) -> 5.5 | BN4: =(MAX(((((Price!$V$7)+((Price!$V$7)*0))/K4)+BL4),500/AF4)) -> 6 | BO4: =(((MAX((($BO$5*L4)),300))/E4)/L4) -> 0.71428571 | BP4: =(((MAX((($BP$5*L4)),300))/E4)/L4) -> 0.71428571 | BQ4: =(((MAX((($BQ$5*L4)),300))/L4)/E4) -> 0.71428571 | BR4: =((((MAX((((($BI$5*$BJ$5)*Price!$S$7)*L4)),300))/E4)/L4)+((((MAX((((($BI$5*$BJ$5)*Price!$S$7)*L4)),300))/E4)/L4)*Sheet2!Z35)) -> #VALUE! | BS4: =((MAX((K4*Price!$U$12),300))/K4) -> 5 | BT4: =((MAX((K4*Price!$V$12),300))/K4) -> 6
A5: Kgs. | D5: =(ROUNDUP(((($H$2*$I$2)/1550)*($J$2/1000))*($K$2/$E$2),0)) -> 1 | F5: =ROUNDUP(H2,0) -> 19 | G5: =(H2*I2)/144 -> 2.6388889 | H5: =(CONCATENATE(F5,(ROUNDUP(I2,0)))) -> 1920 | I5: =IFERROR(__xludf.DUMMYFUNCTION("SPLIT(Quotation!D22,""*"")"),"#VALUE!") -> #VALUE! | K5: =((ROUNDUP(I5,0))*(ROUNDUP(J5,0))) -> #VALUE! | L5: =IFERROR(__xludf.DUMMYFUNCTION("SPLIT(Product!CG5,"" "")"),280.0) -> 280 | M5: =IFERROR(__xludf.DUMMYFUNCTION("""COMPUTED_VALUE"""),"GSM") -> GSM | AG5: =((((F5*I2)*Price!W12)/E2)*Product!CF74) -> 0 | AH5: =(Product!$CH$155*Product!$CG$110*Product!$BB$15) -> 275 | AJ5: =((((F5*I2)*Price!X12)/E2)*Product!CF74) -> 0 | AL5: =IFERROR(__xludf.DUMMYFUNCTION("iferror((SPLIT(Quotation!E21,""*"")))"),"") | AW5: =(Quotation!B26) | BI5: =IFERROR(__xludf.DUMMYFUNCTION("(SPLIT(Quotation!E26,""*""))"),"#VALUE!") -> #VALUE! | BO5: =((((((Product5!$Z16+Product5!$AA16)+((Product5!$Z16+Product5!$AA16)*0.2))*Price!$W7)))+((((((Product5!$Z16+Product5!$AA16)+((Product5!$Z16+Product5!$AA16)*0.2))*Price!$W7)))*0)) -> 0 | BP5: =(((Price!$W$7*2)+((Price!$W$7*2)*0.2))) -> 0.24 | BQ5: =((((((Product5!$Z16+Product5!$AA16)+((Product5!$Z16+Product5!$AA16)*0.2))*Price!$X7)))+((((((Product5!$Z16+Product5!$AA16)+((Product5!$Z16+Product5!$AA16)*0.2))*Price!$X7)))*0)) -> 0 | BR5: =IFERROR(__xludf.DUMMYFUNCTION("(SPLIT(Quotation!E27,""*""))"),"#VALUE!") -> #VALUE! | BU5: =Quotation!H27/AF2 -> 0
A6: =Sheet2!A6 -> #N/A | B6: =Sheet2!B6 | C6: =Sheet2!C6 | D6: =Sheet2!D6 | E6: =Max(Sheet2!E6,Sheet2!E8) -> 2 | F6: =Product2!CE74 -> 2029 | G6: =Product2!BI45 -> 1926 | H6: =Max(Sheet2!G6,Sheet2!G8) -> 18 | I6: =Max(Sheet2!H6,Sheet2!H8) -> 25 | J6: =L9 -> 170 | K6: =Product2!H2 -> 500 | L6: =ROUNDUP((K6/E6)+80,0) -> 330 | M6: =ROUNDUP(((K6/E6)*Sheet2!$AB$6)+80,0) -> 330 | N6: =Roundup((K6/E6),0) -> 250 | P6: =(Roundup((((((H6*I6)/1550)*(J6/1000))*(Product2!$CC$5+2))*L6)+((L6/144)*15),0)) -> 1289 | U6: =Roundup(((((Product2!$BZ$5+1))*L6)+((L6/144)*10)),0) -> 25103 | V6: 100 | W6: =Roundup(F9*I6*M6*Sheet2!E80*Sheet2!E72,0) -> 0 | X6: =IFNA((IFS(F6=1926,LOOKUP(M6,(Price!$AA$1:$AB$300),(Price!$AC$1:$AC$300)),F6=2029,LOOKUP(M6,(Price!$AA$1:$AB$300),(Price!$AF$1:$AF$300)),F6=3001,LOOKUP(N6,(Price!$AI$2:$AJ$8),(Price!$AK$2:$AK$8)),F6=2030,LOOKUP(M6,(Price!$AA$1:$AB$300),(Price!$BE$1:$BE$300)),F6=2841,LOOKUP(M6,(Price!$AA$1:$AB$300),(Price!$BF$1:$BF$300)),F6=2840,LOOKUP(M6,(Price!$AA$1:$AB$300),(Price!$AG$1:$AG$300)))),"")*Product2!$BB$15+$AH$9+W6 -> 2300 | Y6: =IFNA(IFS(G6=1002,LOOKUP(O6,(Price!$AI$2:$AJ$8),(Price!$AL$2:$AL$8)),G6=1003,lookup(O6,(Price!$AI$2:$AJ$8),(Price!$AM$2:$AM$8)),G6=1004,lookup(O6,(Price!$AI$2:$AJ$8),(Price!$AN$2:$AN$8))),"")*Product2!$BB$15 -> 0 | Z6: =(LOOKUP(L6,(Price!$AA$2:$AB$300),(Price!$AD$2:$AD$300)))*Sheet2!Z12 -> 300 | AA6: =Sheet2!K6 | AB6: =Sheet2!L6 | AC6: =Sheet2!M6 | AD6: =ROUNDUP(((K6*AB6)+((K6*AB6)*5%))+(Max(((L6*E6)*AC6),200)+1),0) -> 201 | AE6: =ROUNDUP(V6+Z6+AA6+AB6+AC6,0) -> 400 | AF6: =K6 -> 500 | AG6: =(((((P6+AE6+X6+AD6)/AF6))*(0))+((P6+AE6+X6+AD6)/AF6))+$AG$9 -> 8.38 | AL6: =(((((U6+AE6+X6+AD6)/AF6)*(0))+((U6+AE6+X6+AD6)/AF6)))+$AJ$9 -> 56.008 | AM6: =((((((Roundup((((((AL$9*AM$9)/1550)*(J6/1000))*(Product2!$CC$5+2))*L6)+((L6/144)*15),0))+AE6+X6+AD6)/AF6))*(0))+(((Roundup((((((AL$9*AM$9)/1550)*(J6/1000))*(Product2!$CC$5+2))*L6)+((L6/144)*15),0))+AE6+X6+AD6)/AF6))+$AG$9 -> 8.38 | AW6: =MAX((((H6*I6)*(Price!$T$2)*L6)/AF6),300/AF6) -> 2.376 | AX6: =MAX((((H6*I6)*(Price!$S$2)*L6)/AF6),300/AF6) -> 0.9801 | AY6: =MAX((((H6*I6)*(Price!$S$3)*L6)/AF6),300/AF6) -> 1.3068 | AZ6: =MAX((((H6*I6)*(Price!$V$2)*L6)/AF6),300/AF6) -> 0.6 | BA6: =MAX(((((H6*I6)*(Price!$W$2)*L6)/AF6)+(350/AF6)),500/AF6) -> 1.4425 | BB6: =MAX(((((H6*I6)*(Price!$Y$7)*L6)/AF6)+(350/AF6)),2500/AF6)+AW6 -> 7.376 | BC6: =MAX(((((H6*I6)*(Price!$U$2)*L6)/AF6)+(350/AF6)),2500/AF6) -> 5 | BD6: =(MAX(BE6:BF6)) -> 5.276 | BE6: =(MAX((((((((Price!$X$2)*0.17)+(Price!$X$2))*L6)+(350))/AF6)+AW6),500/AF6)) -> 3.8482 | BF6: =((((Price!$Y$2)+350)/AF6)+AW6) -> 5.276 | BG6: =IFERROR(__xludf.DUMMYFUNCTION("(SPLIT(Quotation!$D$30,""*""))"),"#VALUE!") -> #VALUE! | BI6: =(Max(((((((H6*I6)*Price!$R$7)*L6)/AF6)*0)+((((H6*I6)*Price!$R$7)*L6)/AF6)+BQ6),500/AF6)) -> 4.1670455 | BJ6: =(MAX((((BG6*2)*Price!$S$7)+(((BG6*2)*Price!$S$7)*0)+BQ6),500/AF6)) -> #VALUE! | BK6: =(MAX(((((BG6*2)+(BH6*2))*Price!$S$7)+((((BG6*2)+(BH6*2))*Price!$S$7)*0)+BQ6),500/AF6)) -> #VALUE! | BL6: =(MAX((((LOOKUP(K6,(Price!$AA$2:$AB$1199),(Price!$AE$2:$AE$1199)))+((LOOKUP(K6,(Price!$AA$2:$AB$1199),(Price!$AE$2:$AE$1199)))*0))+BQ6),500/AF6)) -> 1 | BM6: =(MAX(((((Price!$U$7)+((Price!$U$7)*0))/K6)+BL6),500/AF6)) -> 1.1 | BN6: =(MAX(((((Price!$V$7)+((Price!$V$7)*0))/K6)+BL6),500/AF6)) -> 1.2 | BO6: =(((MAX((Roundup($BO$9*L6,0)),300))/E6)/L6) -> 0.45454545 | BP6: =(((MAX((Roundup($BP$5*L6,0)),300))/E6)/L6) -> 0.45454545 | BQ6: =(((MAX((($BQ$9*L6)),300))/L6)/E6) -> 0.45454545 | BR6: =((((MAX((((($BI$9*$BJ$9)*Price!$S$7)*L6)),300))/E6)/L6)+((((MAX((((($BI$9*$BJ$9)*Price!$S$7)*L6)),300))/E6)/L6)*Sheet2!Z37)) -> #VALUE! | BS6: =((MAX((K6*Price!$U$12),300))/K6) -> 5 | BT6: =((MAX((K6*Price!$V$12),300))/K6) -> 6 | BU6: =(iferror(roundup((((MAX((L6*E6*BR9*BS$9*BT$9*Price!Z21),1500))+(BR9*BS9*BT9*E6*Price!Y21)))+((((MAX((L6*E6*BR9*BS$9*BT$9*Price!Z21),1500))+(BR9*BS9*BT9*E6*Price!Y21)))*Sheet2!Z33),0),""))*Product2!CF87 -> 0
A7: =A6 -> #N/A | B7: =B6 | C7: =C6 | D7: =D6 | E7: =E6 -> 2 | F7: =F6 -> 2029 | G7: =G6 -> 1926 | H7: =H6 -> 18 | ... J7: =J6 -> 170 | K7: =Product2!H4 -> 35000 | L7: =ROUNDUP((K7/E7)+80,0) -> 17580 | M7: =ROUNDUP(((K7/E7)*Sheet2!$AB$6)+80,0) -> 17580 | N7: =Roundup((K7/E7),0) -> 17500 | P7: =(Roundup((((((H7*I7)/1550)*(J7/1000))*(Product2!$CC$5+2))*L7)+((L7/144)*15),0)) -> 68641 | U7: =Roundup(((((Product2!$BZ$5+1))*L7)+((L7/144)*10)),0) -> 1337301 | V7: =V6 -> 100 | W7: =Roundup(F9*I6*M7*Sheet2!E80*Sheet2!E72,0) -> 0 | X7: =IFNA((IFS(F7=1926,LOOKUP(M7,(Price!$AA$1:$AB$300),(Price!$AC$1:$AC$300)),F7=2029,LOOKUP(M7,(Price!$AA$1:$AB$300),(Price!$AF$1:$AF$300)),F7=3001,LOOKUP(N7,(Price!$AI$2:$AJ$8),(Price!$AK$2:$AK$8)),F7=2030,LOOKUP(M7,(Price!$AA$1:$AB$300),(Price!$BE$1:$BE$300)),F7=2841,LOOKUP(M7,(Price!$AA$1:$AB$300),(Price!$BF$1:$BF$300)),F7=2840,LOOKUP(M7,(Price!$AA$1:$AB$300),(Price!$AG$1:$AG$300)))),"")*Product2!$BB$15+$AH$9+W7 -> 9100 | Y7: =IFNA(IFS(G7=1002,LOOKUP(O7,(Price!$AI$2:$AJ$8),(Price!$AL$2:$AL$8)),G7=1003,lookup(O7,(Price!$AI$2:$AJ$8),(Price!$AM$2:$AM$8)),G7=1004,lookup(O7,(Price!$AI$2:$AJ$8),(Price!$AN$2:$AN$8))),"")*Product2!$BB$15 -> 0 | Z7: =(LOOKUP(L7,(Price!$AA$2:$AB$300),(Price!$AD$2:$AD$300)))*Sheet2!Z12 -> 5400 | AA7: =AA6 | AB7: =AB6 | AC7: =AC6 | AD7: =ROUNDUP(((K7*AB7)+((K7*AB7)*5%))+(Max(((L7*E7)*AC7),200)+1),0) -> 201 | AE7: =ROUNDUP(V7+Z7+AA7+AB7+AC7,0) -> 5500 | AF7: =K7 -> 35000 | AG7: =(((((P7+AE7+X7+AD7)/AF7))*(0))+((P7+AE7+X7+AD7)/AF7))+$AG$9 -> 2.3840571 | AL7: =(((((U7+AE7+X7+AD7)/AF7)*(0))+((U7+AE7+X7+AD7)/AF7)))+$AJ$9 -> 38.631486 | AM7: =((((((Roundup((((((AL$9*AM$9)/1550)*(J7/1000))*(Product2!$CC$5+2))*L7)+((L7/144)*15),0))+AE7+X7+AD7)/AF7))*(0))+(((Roundup((((((AL$9*AM$9)/1550)*(J7/1000))*(Product2!$CC$5+2))*L7)+((L7/144)*15),0))+AE7+X7+AD7)/AF7))+$AG$9 -> 2.3840571 | AW7: =MAX((((H7*I7)*(Price!$T$2)*L7)/AF7),300/AF7) -> 1.8082286 | AX7: =MAX((((H7*I7)*(Price!$S$2)*L7)/AF7),300/AF7) -> 0.74589429 | AY7: =MAX((((H7*I7)*(Price!$S$3)*L7)/AF7),300/AF7) -> 0.99452571 | AZ7: =MAX((((H7*I7)*(Price!$V$2)*L7)/AF7),300/AF7) -> 0.31644 | BA7: =MAX(((((H7*I7)*(Price!$W$2)*L7)/AF7)+(350/AF7)),500/AF7) -> 0.57507143 | BB7: =MAX(((((H7*I7)*(Price!$Y$7)*L7)/AF7)+(350/AF7)),2500/AF7)+AW7 -> 3.0613857 | BC7: =MAX(((((H7*I7)*(Price!$U$2)*L7)/AF7)+(350/AF7)),2500/AF7) -> 1.0271286 | BD7: =(MAX(BE7:BF7)) -> 2.4059029 | BE7: =(MAX((((((((Price!$X$2)*0.17)+(Price!$X$2))*L7)+(350))/AF7)+AW7),500/AF7)) -> 2.4059029 | BF7: =((((Price!$Y$2)+350)/AF7)+AW7) -> 1.8496571 | BG7: =IFERROR(__xludf.DUMMYFUNCTION("(SPLIT(Quotation!$D$30,""*""))"),"#VALUE!") -> #VALUE! | BI7: =(Max(((((((H7*I7)*Price!$R$7)*L7)/AF7)*0)+((((H7*I7)*Price!$R$7)*L7)/AF7)+BQ7),500/AF7)) -> 2.8338896 | BJ7: =(MAX((((BG7*2)*Price!$S$7)+(((BG7*2)*Price!$S$7)*0)+BQ7),500/AF7)) -> #VALUE! | BK7: =(MAX(((((BG7*2)+(BH7*2))*Price!$S$7)+((((BG7*2)+(BH7*2))*Price!$S$7)*0)+BQ7),500/AF7)) -> #VALUE! | BL7: =(MAX((((LOOKUP(K7,(Price!$AA$2:$AB$1199),(Price!$AE$2:$AE$1199)))+((LOOKUP(K7,(Price!$AA$2:$AB$1199),(Price!$AE$2:$AE$1199)))*0))+BQ7),500/AF7)) -> 0.15853242 | BM7: =(MAX(((((Price!$U$7)+((Price!$U$7)*0))/K7)+BL7),500/AF7)) -> 0.15996099 | BN7: =(MAX(((((Price!$V$7)+((Price!$V$7)*0))/K7)+BL7),500/AF7)) -> 0.16138957 | BO7: =(((MAX((Roundup($BO$9*L7,0)),300))/E7)/L7) -> 0.0085324232 | BP7: =(((MAX((Roundup($BP$5*L7,0)),300))/E7)/L7) -> 0.12002275 | BQ7: =(((MAX((($BQ$9*L7)),300))/L7)/E7) -> 0.0085324232 | BR7: =((((MAX((((($BI$9*$BJ$9)*Price!$S$7)*L7)),300))/E7)/L7)+((((MAX((((($BI$9*$BJ$9)*Price!$S$7)*L7)),300))/E7)/L7)*Sheet2!Z38)) -> #VALUE! | BS7: =((MAX((K7*Price!$U$12),300))/K7) -> 5 | BT7: =((MAX((K7*Price!$V$12),300))/K7) -> 6
A8: =A6 -> #N/A | B8: =B6 | C8: =C6 | D8: =D6 | E8: =E6 -> 2 | F8: =F6 -> 2029 | G8: =G6 -> 1926 | H8: =H6 -> 18 | ... J8: =J6 -> 170 | K8: =Product2!H6 | L8: =ROUNDUP((K8/E8)+80,0) -> 80 | M8: =ROUNDUP(((K8/E8)*Sheet2!$AB$6)+80,0) -> 80 | N8: =Roundup((K8/E8),0) -> 0 | P8: =(Roundup((((((H8*I8)/1550)*(J8/1000))*(Product2!$CC$5+2))*L8)+((L8/144)*15),0)) -> 313 | U8: =Roundup(((((Product2!$BZ$5+1))*L8)+((L8/144)*10)),0) -> 6086 | V8: =V6 -> 100 | W8: =Roundup(F9*I6*M8*Sheet2!E80*Sheet2!E72,0) -> 0 | X8: =IFNA((IFS(F8=1926,LOOKUP(M8,(Price!$AA$1:$AB$300),(Price!$AC$1:$AC$300)),F8=2029,LOOKUP(M8,(Price!$AA$1:$AB$300),(Price!$AF$1:$AF$300)),F8=3001,LOOKUP(N8,(Price!$AI$2:$AJ$8),(Price!$AK$2:$AK$8)),F8=2030,LOOKUP(M8,(Price!$AA$1:$AB$300),(Price!$BE$1:$BE$300)),F8=2841,LOOKUP(M8,(Price!$AA$1:$AB$300),(Price!$BF$1:$BF$300)),F8=2840,LOOKUP(M8,(Price!$AA$1:$AB$300),(Price!$AG$1:$AG$300)))),"")*Product2!$BB$15+$AH$9+W8 -> 2300 | Y8: =IFNA(IFS(G8=1002,LOOKUP(O8,(Price!$AI$2:$AJ$8),(Price!$AL$2:$AL$8)),G8=1003,lookup(O8,(Price!$AI$2:$AJ$8),(Price!$AM$2:$AM$8)),G8=1004,lookup(O8,(Price!$AI$2:$AJ$8),(Price!$AN$2:$AN$8))),"")*Product2!$BB$15 -> 0 | Z8: =(LOOKUP(L8,(Price!$AA$2:$AB$300),(Price!$AD$2:$AD$300)))*Sheet2!Z12 -> 300 | AA8: =AA6 | AB8: =AB6 | AC8: =AC6 | AD8: =ROUNDUP(((K8*AB8)+((K8*AB8)*5%))+(Max(((L8*E8)*AC8),200)+1),0) -> 201 | AE8: =ROUNDUP(V8+Z8+AA8+AB8+AC8,0) -> 400 | AF8: =K8 | AG8: =(((((P8+AE8+X8+AD8)/AF8))*(0))+((P8+AE8+X8+AD8)/AF8))+$AG$9 -> #DIV/0! | AL8: =(((((U8+AE8+X8+AD8)/AF8)*(0))+((U8+AE8+X8+AD8)/AF8)))+$AJ$9 -> #DIV/0! | AM8: =((((((Roundup((((((AL$9*AM$9)/1550)*(J8/1000))*(Product2!$CC$5+2))*L8)+((L8/144)*15),0))+AE8+X8+AD8)/AF8))*(0))+(((Roundup((((((AL$9*AM$9)/1550)*(J8/1000))*(Product2!$CC$5+2))*L8)+((L8/144)*15),0))+AE8+X8+AD8)/AF8))+$AG$9 -> #DIV/0! | AW8: =MAX((((H8*I8)*(Price!$T$2)*L8)/AF8),300/AF8) -> #DIV/0! | AX8: =MAX((((H8*I8)*(Price!$S$2)*L8)/AF8),300/AF8) -> #DIV/0! | AY8: =MAX((((H8*I8)*(Price!$S$3)*L8)/AF8),300/AF8) -> #DIV/0! | AZ8: =MAX((((H8*I8)*(Price!$V$2)*L8)/AF8),300/AF8) -> #DIV/0! | BA8: =MAX(((((H8*I8)*(Price!$W$2)*L8)/AF8)+(350/AF8)),500/AF8) -> #DIV/0! | BB8: =MAX(((((H8*I8)*(Price!$Y$7)*L8)/AF8)+(350/AF8)),2500/AF8)+AW8 -> #DIV/0! | BC8: =MAX(((((H8*I8)*(Price!$U$2)*L8)/AF8)+(350/AF8)),2500/AF8) -> #DIV/0! | BD8: =(MAX(BE8:BF8)) -> #DIV/0! | BE8: =(MAX((((((((Price!$X$2)*0.17)+(Price!$X$2))*L8)+(350))/AF8)+AW8),500/AF8)) -> #DIV/0! | BF8: =((((Price!$Y$2)+350)/AF8)+AW8) -> #DIV/0! | BG8: =IFERROR(__xludf.DUMMYFUNCTION("(SPLIT(Quotation!$D$30,""*""))"),"#VALUE!") -> #VALUE! | BI8: =(Max(((((((H8*I8)*Price!$R$7)*L8)/AF8)*0)+((((H8*I8)*Price!$R$7)*L8)/AF8)+BQ8),500/AF8)) -> #DIV/0! | BJ8: =(MAX((((BG8*2)*Price!$S$7)+(((BG8*2)*Price!$S$7)*0)+BQ8),500/AF8)) -> #VALUE! | BK8: =(MAX(((((BG8*2)+(BH8*2))*Price!$S$7)+((((BG8*2)+(BH8*2))*Price!$S$7)*0)+BQ8),500/AF8)) -> #VALUE! | BL8: =(MAX((((LOOKUP(K8,(Price!$AA$2:$AB$1199),(Price!$AE$2:$AE$1199)))+((LOOKUP(K8,(Price!$AA$2:$AB$1199),(Price!$AE$2:$AE$1199)))*0))+BQ8),500/AF8)) -> #N/A | BM8: =(MAX(((((Price!$U$7)+((Price!$U$7)*0))/K8)+BL8),500/AF8)) -> #DIV/0! | BN8: =(MAX(((((Price!$V$7)+((Price!$V$7)*0))/K8)+BL8),500/AF8)) -> #DIV/0! | BO8: =(((MAX((Roundup($BO$9*L8,0)),300))/E8)/L8) -> 1.875 | BP8: =(((MAX((Roundup($BP$5*L8,0)),300))/E8)/L8) -> 1.875 | BQ8: =(((MAX((($BQ$9*L8)),300))/L8)/E8) -> 1.875 | BR8: =((((MAX((((($BI$9*$BJ$9)*Price!$S$7)*L8)),300))/E8)/L8)+((((MAX((((($BI$9*$BJ$9)*Price!$S$7)*L8)),300))/E8)/L8)*Sheet2!Z39)) -> #VALUE! | BS8: =((MAX((K8*Price!$U$12),300))/K8) -> #DIV/0! | BT8: =((MAX((K8*Price!$V$12),300))/K8) -> #DIV/0!
D9: =(ROUNDUP(((($H$6*$I$6)/1550)*($J$6/1000))*($K$6/$E$6),0)) -> 13 | F9: =ROUNDUP(H6,0) -> 18 | G9: =(H6*I6)/144 -> 3.125 | H9: =CONCATENATE(F9,ROUNDUP(I6,0)) -> 1825 | I9: =IFERROR(__xludf.DUMMYFUNCTION("SPLIT(Quotation!D30,""*"")"),"#VALUE!") -> #VALUE! | K9: =((ROUNDUP(I9,0))*(ROUNDUP(J9,0))) -> #VALUE! | L9: =IFERROR(__xludf.DUMMYFUNCTION("SPLIT(Product2!CG5,"" "")"),170.0) -> 170 | AG9: =((((F9*I6)*Price!W12)/E6)*Product2!CF74) -> 0 | AH9: =(Product2!$CG$74*Product2!$CG$110*Product2!$BB$15) -> 1100 | AJ9: =((((F9*I6)*Price!X12)/E6)*Product2!CF74) -> 0 | AL9: =IFERROR(__xludf.DUMMYFUNCTION("iferror((SPLIT(Quotation!E29,""*"")))"),18.0) -> 18 | AM9: =IFERROR(__xludf.DUMMYFUNCTION("""COMPUTED_VALUE"""),25.0) -> 25 | AN9: =IFERROR(__xludf.DUMMYFUNCTION("""COMPUTED_VALUE"""),2.0) -> 2 | AW9: =(Quotation!B34) | BI9: =IFERROR(__xludf.DUMMYFUNCTION("(SPLIT(Quotation!E34,""*""))"),"#VALUE!") -> #VALUE! | BO9: =((((((Product6!$Z16+Product6!$AA16)+((Product6!$Z16+Product6!$AA16)*0.2))*Price!$W7)))+((((((Product6!$Z16+Product6!$AA16)+((Product6!$Z16+Product6!$AA16)*0.2))*Price!$W7)))*0)) -> 0 | BQ9: =((((((Product6!$Z16+Product6!$AA16)+((Product6!$Z16+Product6!$AA16)*0.2))*Price!$X7)))+((((((Product6!$Z16+Product6!$AA16)+((Product6!$Z16+Product6!$AA16)*0.2))*Price!$X7)))*0)) -> 0 | BR9: =IFERROR(__xludf.DUMMYFUNCTION("(SPLIT(Quotation!E35,""*""))"),"#VALUE!") -> #VALUE!
A10: =Sheet2!A10 | B10: =Sheet2!B10 -> All | C10: =Sheet2!C10 -> Cashify | D10: =Sheet2!D10 -> Custom Size | E10: =Max(Sheet2!E10,Sheet2!E12) -> 3 | F10: =Product3!CE74 -> 2029 | G10: =Product3!BI45 -> 1926 | H10: =Max(Sheet2!G10,Sheet2!G12) -> 20 | I10: =Max(Sheet2!H10,Sheet2!H12) -> 30 | J10: =L13 -> 90 | K10: =IFNA(Product3!H2,"") -> 30000 | L10: =ROUNDUP((K10/E10)+80,0) -> 10080 | M10: =ROUNDUP(((K10/E10)*Sheet2!$AB$7)+80,0) -> 10080 | N10: =Roundup((K10/E10),0) -> 10000 | P10: =(Roundup((((((H10*I10)/1550)*(J10/1000))*(Product3!$CC$5+2))*L10)+((L10/144)*15),0)) -> 38626 | U10: =Roundup(((((Product3!$BZ$5+1))*L10)+((L10/144)*10)),0) -> 1069180 | V10: 100 | W10: =Roundup(F13*I10*M10*Sheet2!E81*Sheet2!E73,0) -> 0 | X10: =IFNA((IFS(F10=1926,LOOKUP(M10,(Price!$AA$1:$AB$300),(Price!$AC$1:$AC$300)),F10=2029,LOOKUP(M10,(Price!$AA$1:$AB$300),(Price!$AF$1:$AF$300)),F10=3001,LOOKUP(N10,(Price!$AI$2:$AJ$8),(Price!$AK$2:$AK$8)),F10=2030,LOOKUP(M10,(Price!$AA$1:$AB$300),(Price!$BE$1:$BE$300)),F10=2841,LOOKUP(M10,(Price!$AA$1:$AB$300),(Price!$BF$1:$BF$300)),F10=2840,LOOKUP(M10,(Price!$AA$1:$AB$300),(Price!$AG$1:$AG$300)))),"")*Product3!$BB$15+$AH$13+W10 -> 5900 | Y10: =IFNA(IFS(G10=1002,LOOKUP(O10,(Price!$AI$2:$AJ$8),(Price!$AL$2:$AL$8)),G10=1003,lookup(O10,(Price!$AI$2:$AJ$8),(Price!$AM$2:$AM$8)),G10=1004,lookup(O10,(Price!$AI$2:$AJ$8),(Price!$AN$2:$AN$8))),"")*Product3!$BB$15 -> 0 | Z10: =(LOOKUP(L10,(Price!$AA$2:$AB$300),(Price!$AD$2:$AD$300)))*Sheet2!Z13 -> 3000 | AA10: =Sheet2!K10 | AB10: =Sheet2!L10 | AC10: =Sheet2!M10 | AD10: =ROUNDUP(((K10*AB10)+((K10*AB10)*5%))+(Max(((L10*E10)*AC10),200)+1),0) -> 201 | AE10: =ROUNDUP(V10+Z10+AA10+AB10+AC10,0) -> 3100 | AF10: =K10 -> 30000 | AG10: =(((((P10+AE10+X10+AD10)/AF10))*(0))+((P10+AE10+X10+AD10)/AF10))+$AG$13 -> 1.5942333 | AL10: =(((((U10+AE10+X10+AD10)/AF10)*(0))+((U10+AE10+X10+AD10)/AF10)))+$AJ$13 -> 35.946033 | AM10: =((((((Roundup((((((AL$13*AM$13)/1550)*(J10/1000))*(Product3!$CC$5+2))*L10)+((L10/144)*15),0))+AE10+X10+AD10)/AF10))*(0))+(((Roundup((((((AL$13*AM$13)/1550)*(J10/1000))*(Product3!$CC$5+2))*L10)+((L10/144)*15),0))+AE10+X10+AD10)/AF10))+$AG$13 -> 1.5942333 | AW10: =MAX((((H10*I10)*(Price!$T$2)*L10)/AF10),300/AF10) -> 1.6128 | AX10: =MAX((((H10*I10)*(Price!$S$2)*L10)/AF10),300/AF10) -> 0.66528 | AY10: =MAX((((H10*I10)*(Price!$S$3)*L10)/AF10),300/AF10) -> 0.88704 | AZ10: =MAX((((H10*I10)*(Price!$V$2)*L10)/AF10),300/AF10) -> 0.28224 | BA10: =MAX(((((H10*I10)*(Price!$W$2)*L10)/AF10)+(350/AF10)),500/AF10) -> 0.51566667 | BB10: =MAX(((((H10*I10)*(Price!$Y$7)*L10)/AF10)+(350/AF10)),2500/AF10)+AW10 -> 2.7332667 | BC10: =MAX(((((H10*I10)*(Price!$U$2)*L10)/AF10)+(350/AF10)),2500/AF10) -> 0.91886667 | BD10: =(MAX(BE10:BF10)) -> 2.0175867 | BE10: =(MAX((((((((Price!$X$2)*0.17)+(Price!$X$2))*L10)+(350))/AF10)+AW10),500/AF10)) -> 2.0175867 | BF10: =((((Price!$Y$2)+350)/AF10)+AW10) -> 1.6611333 | BG10: =IFERROR(__xludf.DUMMYFUNCTION("(SPLIT(Quotation!$D$38,""*""))"),"#VALUE!") -> #VALUE! | BI10: =(Max(((((((H10*I10)*Price!$R$7)*L10)/AF10)*0)+((((H10*I10)*Price!$R$7)*L10)/AF10)+BQ10),500/AF10)) -> 2.5299206 | BJ10: =(MAX((((BG10*2)*Price!$S$7)+(((BG10*2)*Price!$S$7)*0)+BQ10),500/AF10)) -> #VALUE! | BK10: =(MAX(((((BG10*2)+(BH10*2))*Price!$S$7)+((((BG10*2)+(BH10*2))*Price!$S$7)*0)+BQ10),500/AF10)) -> #VALUE! | BL10: =(MAX((((LOOKUP(K10,(Price!$AA$2:$AB$1199),(Price!$AE$2:$AE$1199)))+((LOOKUP(K10,(Price!$AA$2:$AB$1199),(Price!$AE$2:$AE$1199)))*0))+BQ10),500/AF10)) -> 0.15992063 | BM10: =(MAX(((((Price!$U$7)+((Price!$U$7)*0))/K10)+BL10),500/AF10)) -> 0.1615873 | BN10: =(MAX(((((Price!$V$7)+((Price!$V$7)*0))/K10)+BL10),500/AF10)) -> 0.16325397 | BO10: =(((MAX((Roundup($BO$13*L10,0)),300))/E10)/L10) -> 0.0099206349 | BP10: =(((MAX((Roundup($BP$5*L10,0)),300))/E10)/L10) -> 0.080026455 | BQ10: =(((MAX((($BQ$13*L10)),300))/L10)/E10) -> 0.0099206349 | BR10: =((((MAX((((($BI$13*$BJ$14)*Price!$S$7)*L10)),300))/E10)/L10)+((((MAX((((($BI$13*$BJ$13)*Price!$S$7)*L10)),300))/E10)/L10)*Sheet2!Z41)) -> #VALUE! | BS10: =((MAX((K10*Price!$U$12),300))/K10) -> 5 | BT10: =((MAX((K10*Price!$V$12),300))/K10) -> 6 | BU10: =(iferror(roundup(((((MAX((L10*E10*BR13*BS$13*BT$13*Price!Z21),1500))+(BR13*BS13*BT13*E10*Price!Y21)))+((((MAX((L10*E10*BR13*BS$13*BT$13*Price!Z21),1500))+(BS13*BR13*BT13*E10*Price!Y21)))*Sheet2!Z33)),0),""))*Product3!CF87 -> 0
A11: =A10 | B11: =B10 -> All | C11: =C10 -> Cashify | D11: =D10 -> Custom Size | E11: =E10 -> 3 | F11: =F10 -> 2029 | G11: =G10 -> 1926 | H11: =H10 -> 20 | ... J11: =J10 -> 90 | K11: =IFNA(Product3!H4,"") -> 35000 | L11: =ROUNDUP((K11/E11)+80,0) -> 11747 | M11: =ROUNDUP(((K11/E11)*Sheet2!$AB$7)+80,0) -> 11747 | N11: =Roundup((K11/E11),0) -> 11667 | P11: =(Roundup((((((H11*I11)/1550)*(J11/1000))*(Product3!$CC$5+2))*L11)+((L11/144)*15),0)) -> 45014 | U11: =Roundup(((((Product3!$BZ$5+1))*L11)+((L11/144)*10)),0) -> 1245998 | V11: =V10 -> 100 | W11: =Roundup(F13*I10*M11*Sheet2!E81*Sheet2!E73,0) -> 0 | X11: =IFNA((IFS(F11=1926,LOOKUP(M11,(Price!$AA$1:$AB$300),(Price!$AC$1:$AC$300)),F11=2029,LOOKUP(M11,(Price!$AA$1:$AB$300),(Price!$AF$1:$AF$300)),F11=3001,LOOKUP(N11,(Price!$AI$2:$AJ$8),(Price!$AK$2:$AK$8)),F11=2030,LOOKUP(M11,(Price!$AA$1:$AB$300),(Price!$BE$1:$BE$300)),F11=2841,LOOKUP(M11,(Price!$AA$1:$AB$300),(Price!$BF$1:$BF$300)),F11=2840,LOOKUP(M11,(Price!$AA$1:$AB$300),(Price!$AG$1:$AG$300)))),"")*Product3!$BB$15+$AH$13+W11 -> 6700 | Y11: =IFNA(IFS(G11=1002,LOOKUP(O11,(Price!$AI$2:$AJ$8),(Price!$AL$2:$AL$8)),G11=1003,lookup(O11,(Price!$AI$2:$AJ$8),(Price!$AM$2:$AM$8)),G11=1004,lookup(O11,(Price!$AI$2:$AJ$8),(Price!$AN$2:$AN$8))),"")*Product3!$BB$15 -> 0 | Z11: =(LOOKUP(L11,(Price!$AA$2:$AB$300),(Price!$AD$2:$AD$300)))*Sheet2!Z13 -> 3600 | AA11: =AA10 | AB11: =AB10 | AC11: =AC10 | AD11: =ROUNDUP(((K11*AB11)+((K11*AB11)*5%))+(Max(((L11*E11)*AC11),200)+1),0) -> 201 | AE11: =ROUNDUP(V11+Z11+AA11+AB11+AC11,0) -> 3700 | AF11: =K11 -> 35000 | AG11: =(((((P11+AE11+X11+AD11)/AF11))*(0))+((P11+AE11+X11+AD11)/AF11))+$AG$13 -> 1.589 | AL11: =(((((U11+AE11+X11+AD11)/AF11)*(0))+((U11+AE11+X11+AD11)/AF11)))+$AJ$13 -> 35.902829 | AM11: =((((((Roundup((((((AL$13*AM$13)/1550)*(J11/1000))*(Product3!$CC$5+2))*L11)+((L11/144)*15),0))+AE11+X11+AD11)/AF11))*(0))+(((Roundup((((((AL$13*AM$13)/1550)*(J11/1000))*(Product3!$CC$5+2))*L11)+((L11/144)*15),0))+AE11+X11+AD11)/AF11))+$AG$13 -> 1.589 | AW11: =MAX((((H11*I11)*(Price!$T$2)*L11)/AF11),300/AF11) -> 1.6110171 | AX11: =MAX((((H11*I11)*(Price!$S$2)*L11)/AF11),300/AF11) -> 0.66454457 | AY11: =MAX((((H11*I11)*(Price!$S$3)*L11)/AF11),300/AF11) -> 0.88605943 | AZ11: =MAX((((H11*I11)*(Price!$V$2)*L11)/AF11),300/AF11) -> 0.281928 | BA11: =MAX(((((H11*I11)*(Price!$W$2)*L11)/AF11)+(350/AF11)),500/AF11) -> 0.51344286 | BB11: =MAX(((((H11*I11)*(Price!$Y$7)*L11)/AF11)+(350/AF11)),2500/AF11)+AW11 -> 2.7285914 | BC11: =MAX(((((H11*I11)*(Price!$U$2)*L11)/AF11)+(350/AF11)),2500/AF11) -> 0.91619714 | BD11: =(MAX(BE11:BF11)) -> 2.0137026 | BE11: =(MAX((((((((Price!$X$2)*0.17)+(Price!$X$2))*L11)+(350))/AF11)+AW11),500/AF11)) -> 2.0137026 | BF11: =((((Price!$Y$2)+350)/AF11)+AW11) -> 1.6524457 | BG11: =IFERROR(__xludf.DUMMYFUNCTION("(SPLIT(Quotation!$D$38,""*""))"),"#VALUE!") -> #VALUE! | BI11: =(Max(((((((H11*I11)*Price!$R$7)*L11)/AF11)*0)+((((H11*I11)*Price!$R$7)*L11)/AF11)+BQ11),500/AF11)) -> 2.5257271 | BJ11: =(MAX((((BG11*2)*Price!$S$7)+(((BG11*2)*Price!$S$7)*0)+BQ11),500/AF11)) -> #VALUE! | BK11: =(MAX(((((BG11*2)+(BH11*2))*Price!$S$7)+((((BG11*2)+(BH11*2))*Price!$S$7)*0)+BQ11),500/AF11)) -> #VALUE! | BL11: =(MAX((((LOOKUP(K11,(Price!$AA$2:$AB$1199),(Price!$AE$2:$AE$1199)))+((LOOKUP(K11,(Price!$AA$2:$AB$1199),(Price!$AE$2:$AE$1199)))*0))+BQ11),500/AF11)) -> 0.15851281 | BM11: =(MAX(((((Price!$U$7)+((Price!$U$7)*0))/K11)+BL11),500/AF11)) -> 0.15994138 | BN11: =(MAX(((((Price!$V$7)+((Price!$V$7)*0))/K11)+BL11),500/AF11)) -> 0.16136995 | BO11: =(((MAX((Roundup($BO$13*L11,0)),300))/E11)/L11) -> 0.0085128118 | BP11: =(((MAX((Roundup($BP$5*L11,0)),300))/E11)/L11) -> 0.080020431 | BQ11: =(((MAX((($BQ$13*L11)),300))/L11)/E11) -> 0.0085128118 | BR11: =((((MAX((((($BI$13*$BJ$14)*Price!$S$7)*L11)),300))/E11)/L11)+((((MAX((((($BI$13*$BJ$13)*Price!$S$7)*L11)),300))/E11)/L11)*Sheet2!Z42)) -> #VALUE! | BS11: =((MAX((K11*Price!$U$12),300))/K11) -> 5 | BT11: =((MAX((K11*Price!$V$12),300))/K11) -> 6
A12: =A10 | B12: =B10 -> All | C12: =C10 -> Cashify | D12: =D10 -> Custom Size | E12: =E10 -> 3 | F12: =F10 -> 2029 | G12: =G10 -> 1926 | H12: =H10 -> 20 | ... J12: =J10 -> 90 | K12: =IFNA(Product3!H6,"") | L12: =ROUNDUP((K12/E12)+80,0) -> 80 | M12: =ROUNDUP(((K12/E12)*Sheet2!$AB$7)+80,0) -> 80 | N12: =Roundup((K12/E12),0) -> 0 | P12: =(Roundup((((((H12*I12)/1550)*(J12/1000))*(Product3!$CC$5+2))*L12)+((L12/144)*15),0)) -> 307 | U12: =Roundup(((((Product3!$BZ$5+1))*L12)+((L12/144)*10)),0) -> 8486 | V12: =V10 -> 100 | W12: =Roundup(F13*I10*M12*Sheet2!E81*Sheet2!E73,0) -> 0 | X12: =IFNA((IFS(F12=1926,LOOKUP(M12,(Price!$AA$1:$AB$300),(Price!$AC$1:$AC$300)),F12=2029,LOOKUP(M12,(Price!$AA$1:$AB$300),(Price!$AF$1:$AF$300)),F12=3001,LOOKUP(N12,(Price!$AI$2:$AJ$8),(Price!$AK$2:$AK$8)),F12=2030,LOOKUP(M12,(Price!$AA$1:$AB$300),(Price!$BE$1:$BE$300)),F12=2841,LOOKUP(M12,(Price!$AA$1:$AB$300),(Price!$BF$1:$BF$300)),F12=2840,LOOKUP(M12,(Price!$AA$1:$AB$300),(Price!$AG$1:$AG$300)))),"")*Product3!$BB$15+$AH$13+W12 -> 2300 | Y12: =IFNA(IFS(G12=1002,LOOKUP(O12,(Price!$AI$2:$AJ$8),(Price!$AL$2:$AL$8)),G12=1003,lookup(O12,(Price!$AI$2:$AJ$8),(Price!$AM$2:$AM$8)),G12=1004,lookup(O12,(Price!$AI$2:$AJ$8),(Price!$AN$2:$AN$8))),"")*Product3!$BB$15 -> 0 | Z12: =(LOOKUP(L12,(Price!$AA$2:$AB$300),(Price!$AD$2:$AD$300)))*Sheet2!Z13 -> 300 | AA12: =AA10 | AB12: =AB10 | AC12: =AC10 | AD12: =ROUNDUP(((K12*AB12)+((K12*AB12)*5%))+(Max(((L12*E12)*AC12),200)+1),0) -> 201 | AE12: =ROUNDUP(V12+Z12+AA12+AB12+AC12,0) -> 400 | AF12: =K12 | AG12: =(((((P12+AE12+X12+AD12)/AF12))*(0))+((P12+AE12+X12+AD12)/AF12))+$AG$13 -> #DIV/0! | AL12: =(((((U12+AE12+X12+AD12)/AF12)*(0))+((U12+AE12+X12+AD12)/AF12)))+$AJ$13 -> #DIV/0! | AM12: =((((((Roundup((((((AL$13*AM$13)/1550)*(J12/1000))*(Product3!$CC$5+2))*L12)+((L12/144)*15),0))+AE12+X12+AD12)/AF12))*(0))+(((Roundup((((((AL$13*AM$13)/1550)*(J12/1000))*(Product3!$CC$5+2))*L12)+((L12/144)*15),0))+AE12+X12+AD12)/AF12))+$AG$13 -> #DIV/0! | AW12: =MAX((((H12*I12)*(Price!$T$2)*L12)/AF12),300/AF12) -> #DIV/0! | AX12: =MAX((((H12*I12)*(Price!$S$2)*L12)/AF12),300/AF12) -> #DIV/0! | AY12: =MAX((((H12*I12)*(Price!$S$3)*L12)/AF12),300/AF12) -> #DIV/0! | AZ12: =MAX((((H12*I12)*(Price!$V$2)*L12)/AF12),300/AF12) -> #DIV/0! | BA12: =MAX(((((H12*I12)*(Price!$W$2)*L12)/AF12)+(350/AF12)),500/AF12) -> #DIV/0! | BB12: =MAX(((((H12*I12)*(Price!$Y$7)*L12)/AF12)+(350/AF12)),2500/AF12)+AW12 -> #DIV/0! | BC12: =MAX(((((H12*I12)*(Price!$U$2)*L12)/AF12)+(350/AF12)),2500/AF12) -> #DIV/0! | BD12: =(MAX(BE12:BF12)) -> #DIV/0! | BE12: =(MAX((((((((Price!$X$2)*0.17)+(Price!$X$2))*L12)+(350))/AF12)+AW12),500/AF12)) -> #DIV/0! | BF12: =((((Price!$Y$2)+350)/AF12)+AW12) -> #DIV/0! | BG12: =IFERROR(__xludf.DUMMYFUNCTION("(SPLIT(Quotation!$D$38,""*""))"),"#VALUE!") -> #VALUE! | BI12: =(Max(((((((H12*I12)*Price!$R$7)*L12)/AF12)*0)+((((H12*I12)*Price!$R$7)*L12)/AF12)+BQ12),500/AF12)) -> #DIV/0! | BJ12: =(MAX((((BG12*2)*Price!$S$7)+(((BG12*2)*Price!$S$7)*0)+BQ12),500/AF12)) -> #VALUE! | BK12: =(MAX(((((BG12*2)+(BH12*2))*Price!$S$7)+((((BG12*2)+(BH12*2))*Price!$S$7)*0)+BQ12),500/AF12)) -> #VALUE! | BL12: =(MAX((((LOOKUP(K12,(Price!$AA$2:$AB$1199),(Price!$AE$2:$AE$1199)))+((LOOKUP(K12,(Price!$AA$2:$AB$1199),(Price!$AE$2:$AE$1199)))*0))+BQ12),500/AF12)) -> #N/A | BM12: =(MAX(((((Price!$U$7)+((Price!$U$7)*0))/K12)+BL12),500/AF12)) -> #DIV/0! | BN12: =(MAX(((((Price!$V$7)+((Price!$V$7)*0))/K12)+BL12),500/AF12)) -> #DIV/0! | BO12: =(((MAX((Roundup($BO$13*L12,0)),300))/E12)/L12) -> 1.25 | BP12: =(((MAX((Roundup($BP$5*L12,0)),300))/E12)/L12) -> 1.25 | BQ12: =(((MAX((($BQ$13*L12)),300))/L12)/E12) -> 1.25 | BR12: =((((MAX((((($BI$13*$BJ$14)*Price!$S$7)*L12)),300))/E12)/L12)+((((MAX((((($BI$13*$BJ$13)*Price!$S$7)*L12)),300))/E12)/L12)*Sheet2!Z43)) -> #VALUE! | BS12: =((MAX((K12*Price!$U$12),300))/K12) -> #DIV/0! | BT12: =((MAX((K12*Price!$V$12),300))/K12) -> #DIV/0!
D13: =(ROUNDUP(((($H$10*$I$10)/1550)*($J$10/1000))*($K$10/$E$10),0)) -> 349 | F13: =ROUNDUP(H10,0) -> 20 | G13: =(H10*I10)/144 -> 4.1666667 | H13: =CONCATENATE(F13,ROUNDUP(I10,0)) -> 2030 | I13: =IFERROR(__xludf.DUMMYFUNCTION("SPLIT(Quotation!D38,""*"")"),"#VALUE!") -> #VALUE! | K13: =((ROUNDUP(I13,0))*(ROUNDUP(J13,0))) -> #VALUE! | L13: =IFERROR(__xludf.DUMMYFUNCTION("SPLIT(Product3!CG5,"" "")"),90.0) -> 90 | AG13: =((((F13*I10)*Price!W12)/E10)*Product3!CF74) -> 0 | AH13: =(Product3!$CG$74*Product3!$CG$110*Product3!$BB$15) -> 1100 | AJ13: =((((F13*I10)*Price!X12)/E10)*Product3!CF74) -> 0 | AL13: =IFERROR(__xludf.DUMMYFUNCTION("iferror((SPLIT(Quotation!E37,""*"")))"),20.0) -> 20 | AM13: =IFERROR(__xludf.DUMMYFUNCTION("""COMPUTED_VALUE"""),30.0) -> 30 | AN13: =IFERROR(__xludf.DUMMYFUNCTION("""COMPUTED_VALUE"""),3.0) -> 3 | AW13: =(Quotation!B42) | BI13: =IFERROR(__xludf.DUMMYFUNCTION("(SPLIT(Quotation!E42,""*""))"),"#VALUE!") -> #VALUE! | BO13: =((((((Product7!$Z16+Product7!$AA16)+((Product7!$Z16+Product7!$AA16)*0.2))*Price!$W7)))+((((((Product7!$Z16+Product7!$AA16)+((Product7!$Z16+Product7!$AA16)*0.2))*Price!$W7)))*0)) -> 0 | BQ13: =((((((Product7!$Z16+Product7!$AA16)+((Product7!$Z16+Product7!$AA16)*0.2))*Price!$X7)))+((((((Product7!$Z16+Product7!$AA16)+((Product7!$Z16+Product7!$AA16)*0.2))*Price!$X7)))*0)) -> 0 | BR13: =IFERROR(__xludf.DUMMYFUNCTION("(SPLIT(Quotation!E43,""*""))"),"#VALUE!") -> #VALUE!
A14: =Sheet2!A14 -> https://drive.google.com/open?id=1AT8COyVu1i54kTQbeZJnxYi8bjYPzfhK&authuser=jay.agg%40gmail.com&usp=drive_fs | B14: =Sheet2!B14 -> Flyer | C14: =Sheet2!C14 -> A5 | D14: =Sheet2!D14 -> 148 × 210 millimeters or 5.8 × 8.3 inches | E14: =Max(Sheet2!E14,Sheet2!E16) -> 8 | F14: =Product4!CE74 -> 1926 | G14: =Product4!BI45 -> 1926 | H14: =Max(Sheet2!G14,Sheet2!G16) -> 18 | I14: =Max(Sheet2!H14,Sheet2!H16) -> 25 | J14: =L17 -> 90 | K14: =IFNA(Product4!H2,"") -> 100000 | L14: =ROUNDUP((K14/E14)+80,0) -> 12580 | M14: =ROUNDUP(((K14/E14)*Sheet2!$AB$8)+80,0) -> 25080 | N14: =Roundup((K14/E14),0) -> 12500 | P14: =(Roundup((((((H14*I14)/1550)*(J14/1000))*(Product4!$CC$5+2))*L14)+((L14/144)*15),0)) -> 39769 | U14: =Roundup(((((Product4!$BZ$5+1))*L14)+((L14/144)*10)),0) -> 1460154 | V14: 100 | W14: =Roundup(F17*I14*M14*Sheet2!E82*Sheet2!E74,0) -> 0 | X14: =IFNA((IFS(F14=1926,LOOKUP(M14,(Price!$AA$1:$AB$300),(Price!$AC$1:$AC$300)),F14=2029,LOOKUP(M14,(Price!$AA$1:$AB$300),(Price!$AF$1:$AF$300)),F14=3001,LOOKUP(N14,(Price!$AI$2:$AJ$8),(Price!$AK$2:$AK$8)),F14=2030,LOOKUP(M14,(Price!$AA$1:$AB$300),(Price!$BE$1:$BE$300)),F14=2841,LOOKUP(M14,(Price!$AA$1:$AB$300),(Price!$BF$1:$BF$300)),F14=2840,LOOKUP(M14,(Price!$AA$1:$AB$300),(Price!$AG$1:$AG$300)))),"")*Product4!$BB$15+$AH$17+W14 -> 13500 | Y14: =IFNA(IFS(G14=1002,LOOKUP(O14,(Price!$AI$2:$AJ$8),(Price!$AL$2:$AL$8)),G14=1003,lookup(O14,(Price!$AI$2:$AJ$8),(Price!$AM$2:$AM$8)),G14=1004,lookup(O14,(Price!$AI$2:$AJ$8),(Price!$AN$2:$AN$8))),"")*Product4!$BB$15 -> 0 | Z14: =(LOOKUP(L14,(Price!$AA$2:$AB$300),(Price!$AD$2:$AD$300)))*Sheet2!Z14 -> 0 | AA14: =Sheet2!K14 | AB14: =Sheet2!L14 | AC14: =Sheet2!M14 -> 0.03 | AD14: =ROUNDUP(((K14*AB14)+((K14*AB14)*5%))+(Max(((L14*E14)*AC14),200)+1),0) -> 3021 | AE14: =ROUNDUP(V14+Z14+AA14+AB14+AC14,0) -> 101 | AF14: =K14 -> 100000 | AG14: =(((((P14+AE14+X14+AD14)/AF14))*(0))+((P14+AE14+X14+AD14)/AF14))+$AG$17 -> 0.56391 | AL14: =(((((U14+AE14+X14+AD14)/AF14)*(0))+((U14+AE14+X14+AD14)/AF14)))+$AJ$17 -> 14.76776 | AM14: =((((((Roundup((((((AL$17*AM$17)/1550)*(J14/1000))*(Product4!$CC$5+2))*L14)+((L14/144)*15),0))+AE14+X14+AD14)/AF14))*(0))+(((Roundup((((((AL$17*AM$17)/1550)*(J14/1000))*(Product4!$CC$5+2))*L14)+((L14/144)*15),0))+AE14+X14+AD14)/AF14))+$AG$17 -> 0.17933 | AW14: =MAX((((H14*I14)*(Price!$T$2)*L14)/AF14),300/AF14) -> 0.45288 | AX14: =MAX((((H14*I14)*(Price!$S$2)*L14)/AF14),300/AF14) -> 0.186813 | AY14: =MAX((((H14*I14)*(Price!$S$3)*L14)/AF14),300/AF14) -> 0.249084 | AZ14: =MAX((((H14*I14)*(Price!$V$2)*L14)/AF14),300/AF14) -> 0.079254 | BA14: =MAX(((((H14*I14)*(Price!$W$2)*L14)/AF14)+(350/AF14)),500/AF14) -> 0.145025 | BB14: =MAX(((((H14*I14)*(Price!$Y$7)*L14)/AF14)+(350/AF14)),2500/AF14)+AW14 -> 0.767735 | BC14: =MAX(((((H14*I14)*(Price!$U$2)*L14)/AF14)+(350/AF14)),2500/AF14) -> 0.258245 | BD14: =(MAX(BE14:BF14)) -> 0.603566 | BE14: =(MAX((((((((Price!$X$2)*0.17)+(Price!$X$2))*L14)+(350))/AF14)+AW14),500/AF14)) -> 0.603566 | BF14: =((((Price!$Y$2)+350)/AF14)+AW14) -> 0.46738 | BG14: =IFERROR(__xludf.DUMMYFUNCTION("(SPLIT(Quotation!$D$46,""*""))"),"#VALUE!") -> #VALUE! | BI14: =(Max(((((((H14*I14)*Price!$R$7)*L14)/AF14)*0)+((((H14*I14)*Price!$R$7)*L14)/AF14)+BQ14),500/AF14)) -> 0.71060592 | BJ14: =(MAX((((BG14*2)*Price!$S$7)+(((BG14*2)*Price!$S$7)*0)+BQ14),500/AF14)) -> #VALUE! | BK14: =(MAX(((((BG14*2)+(BH14*2))*Price!$S$7)+((((BG14*2)+(BH14*2))*Price!$S$7)*0)+BQ14),500/AF14)) -> #VALUE! | BL14: =(MAX((((LOOKUP(K14,(Price!$AA$2:$AB$1199),(Price!$AE$2:$AE$1199)))+((LOOKUP(K14,(Price!$AA$2:$AB$1199),(Price!$AE$2:$AE$1199)))*0))+BQ14),500/AF14)) -> 0.15298092 | BM14: =(MAX(((((Price!$U$7)+((Price!$U$7)*0))/K14)+BL14),500/AF14)) -> 0.15348092 | BN14: =(MAX(((((Price!$V$7)+((Price!$V$7)*0))/K14)+BL14),500/AF14)) -> 0.15398092 | BO14: =(((MAX((Roundup($BO$17*L14,0)),300))/E14)/L14) -> 0.0029809221 | BP14: =(((MAX((Roundup($BP$5*L14,0)),300))/E14)/L14) -> 0.030007949 | BQ14: =(((MAX((($BQ$17*L14)),300))/L14)/E14) -> 0.0029809221 | BR14: =((((MAX((((($BI$17*$BJ$17)*Price!$S$7)*L14)),300))/E14)/L14)+((((MAX((((($BI$17*$BJ$17)*Price!$S$7)*L14)),300))/E14)/L14)*Sheet2!Z45)) -> #VALUE! | BS14: =((MAX((K14*Price!$U$12),300))/K14) -> 5 | BT14: =((MAX((K14*Price!$V$12),300))/K14) -> 6 | BU14: =(iferror(roundup((((MAX((L14*E14*BR17*BS$17*BT$17*Price!Z21),1500))+(BR17*BS17*BT17*E14*Price!Y21)))+((((MAX((L14*E14*BR17*BS$17*BT$17*Price!Z21),1500))+(BR17*BS17*BT17*E14*Price!Y21)))*Sheet2!Z33),0),""))*Product4!CF87 -> 0
A15: =A14 -> https://drive.google.com/open?id=1AT8COyVu1i54kTQbeZJnxYi8bjYPzfhK&authuser=jay.agg%40gmail.com&usp=drive_fs | B15: =B14 -> Flyer | C15: =C14 -> A5 | D15: =D14 -> 148 × 210 millimeters or 5.8 × 8.3 inches | E15: =E14 -> 8 | F15: =F14 -> 1926 | G15: =G14 -> 1926 | H15: =H14 -> 18 | ... J15: =J14 -> 90 | K15: =IFNA(Product4!H4,"") -> 50000 | L15: =ROUNDUP((K15/E15)+80,0) -> 6330 | M15: =ROUNDUP(((K15/E15)*Sheet2!$AB$8)+80,0) -> 12580 | N15: =Roundup((K15/E15),0) -> 6250 | P15: =(Roundup((((((H15*I15)/1550)*(J15/1000))*(Product4!$CC$5+2))*L15)+((L15/144)*15),0)) -> 20011 | U15: =Roundup(((((Product4!$BZ$5+1))*L15)+((L15/144)*10)),0) -> 734720 | V15: =V14 -> 100 | W15: =Roundup(F17*I14*M15*Sheet2!E82*Sheet2!E74,0) -> 0 | X15: =IFNA((IFS(F15=1926,LOOKUP(M15,(Price!$AA$1:$AB$300),(Price!$AC$1:$AC$300)),F15=2029,LOOKUP(M15,(Price!$AA$1:$AB$300),(Price!$AF$1:$AF$300)),F15=3001,LOOKUP(N15,(Price!$AI$2:$AJ$8),(Price!$AK$2:$AK$8)),F15=2030,LOOKUP(M15,(Price!$AA$1:$AB$300),(Price!$BE$1:$BE$300)),F15=2841,LOOKUP(M15,(Price!$AA$1:$AB$300),(Price!$BF$1:$BF$300)),F15=2840,LOOKUP(M15,(Price!$AA$1:$AB$300),(Price!$AG$1:$AG$300)))),"")*Product4!$BB$15+$AH$17+W15 -> 7500 | Y15: =IFNA(IFS(G15=1002,LOOKUP(O15,(Price!$AI$2:$AJ$8),(Price!$AL$2:$AL$8)),G15=1003,lookup(O15,(Price!$AI$2:$AJ$8),(Price!$AM$2:$AM$8)),G15=1004,lookup(O15,(Price!$AI$2:$AJ$8),(Price!$AN$2:$AN$8))),"")*Product4!$BB$15 -> 0 | Z15: =(LOOKUP(L15,(Price!$AA$2:$AB$300),(Price!$AD$2:$AD$300)))*Sheet2!Z14 -> 0 | AA15: =AA14 | AB15: =AB14 | AC15: =AC14 -> 0.03 | AD15: =ROUNDUP(((K15*AB15)+((K15*AB15)*5%))+(Max(((L15*E15)*AC15),200)+1),0) -> 1521 | AE15: =ROUNDUP(V15+Z15+AA15+AB15+AC15,0) -> 101 | AF15: =K15 -> 50000 | AG15: =(((((P15+AE15+X15+AD15)/AF15))*(0))+((P15+AE15+X15+AD15)/AF15))+$AG$17 -> 0.58266 | AL15: =(((((U15+AE15+X15+AD15)/AF15)*(0))+((U15+AE15+X15+AD15)/AF15)))+$AJ$17 -> 14.87684 | AM15: =((((((Roundup((((((AL$17*AM$17)/1550)*(J15/1000))*(Product4!$CC$5+2))*L15)+((L15/144)*15),0))+AE15+X15+AD15)/AF15))*(0))+(((Roundup((((((AL$17*AM$17)/1550)*(J15/1000))*(Product4!$CC$5+2))*L15)+((L15/144)*15),0))+AE15+X15+AD15)/AF15))+$AG$17 -> 0.19564 | AW15: =MAX((((H15*I15)*(Price!$T$2)*L15)/AF15),300/AF15) -> 0.45576 | AX15: =MAX((((H15*I15)*(Price!$S$2)*L15)/AF15),300/AF15) -> 0.188001 | AY15: =MAX((((H15*I15)*(Price!$S$3)*L15)/AF15),300/AF15) -> 0.250668 | AZ15: =MAX((((H15*I15)*(Price!$V$2)*L15)/AF15),300/AF15) -> 0.079758 | BA15: =MAX(((((H15*I15)*(Price!$W$2)*L15)/AF15)+(350/AF15)),500/AF15) -> 0.149425 | BB15: =MAX(((((H15*I15)*(Price!$Y$7)*L15)/AF15)+(350/AF15)),2500/AF15)+AW15 -> 0.776095 | BC15: =MAX(((((H15*I15)*(Price!$U$2)*L15)/AF15)+(350/AF15)),2500/AF15) -> 0.263365 | BD15: =(MAX(BE15:BF15)) -> 0.610882 | BE15: =(MAX((((((((Price!$X$2)*0.17)+(Price!$X$2))*L15)+(350))/AF15)+AW15),500/AF15)) -> 0.610882 | BF15: =((((Price!$Y$2)+350)/AF15)+AW15) -> 0.48476 | BG15: =IFERROR(__xludf.DUMMYFUNCTION("(SPLIT(Quotation!$D$46,""*""))"),"#VALUE!") -> #VALUE! | BI15: =(Max(((((((H15*I15)*Price!$R$7)*L15)/AF15)*0)+((((H15*I15)*Price!$R$7)*L15)/AF15)+BQ15),500/AF15)) -> 0.71804917 | BJ15: =(MAX((((BG15*2)*Price!$S$7)+(((BG15*2)*Price!$S$7)*0)+BQ15),500/AF15)) -> #VALUE! | BK15: =(MAX(((((BG15*2)+(BH15*2))*Price!$S$7)+((((BG15*2)+(BH15*2))*Price!$S$7)*0)+BQ15),500/AF15)) -> #VALUE! | BL15: =(MAX((((LOOKUP(K15,(Price!$AA$2:$AB$1199),(Price!$AE$2:$AE$1199)))+((LOOKUP(K15,(Price!$AA$2:$AB$1199),(Price!$AE$2:$AE$1199)))*0))+BQ15),500/AF15)) -> 0.15592417 | BM15: =(MAX(((((Price!$U$7)+((Price!$U$7)*0))/K15)+BL15),500/AF15)) -> 0.15692417 | BN15: =(MAX(((((Price!$V$7)+((Price!$V$7)*0))/K15)+BL15),500/AF15)) -> 0.15792417 | BO15: =(((MAX((Roundup($BO$17*L15,0)),300))/E15)/L15) -> 0.0059241706 | BP15: =(((MAX((Roundup($BP$5*L15,0)),300))/E15)/L15) -> 0.030015798 | BQ15: =(((MAX((($BQ$17*L15)),300))/L15)/E15) -> 0.0059241706 | BR15: =((((MAX((((($BI$17*$BJ$17)*Price!$S$7)*L15)),300))/E15)/L15)+((((MAX((((($BI$17*$BJ$17)*Price!$S$7)*L15)),300))/E15)/L15)*Sheet2!Z46)) -> #VALUE! | BS15: =((MAX((K15*Price!$U$12),300))/K15) -> 5 | BT15: =((MAX((K15*Price!$V$12),300))/K15) -> 6
A16: =A14 -> https://drive.google.com/open?id=1AT8COyVu1i54kTQbeZJnxYi8bjYPzfhK&authuser=jay.agg%40gmail.com&usp=drive_fs | B16: =B14 -> Flyer | C16: =C14 -> A5 | D16: =D14 -> 148 × 210 millimeters or 5.8 × 8.3 inches | E16: =E14 -> 8 | F16: =F14 -> 1926 | G16: =G14 -> 1926 | H16: =H14 -> 18 | ... J16: =J14 -> 90 | K16: =IFNA(Product4!H6,"") | L16: =ROUNDUP((K16/E16)+80,0) -> 80 | M16: =ROUNDUP(((K16/E16)*Sheet2!$AB$8)+80,0) -> 80 | N16: =Roundup((K16/E16),0) -> 0 | P16: =(Roundup((((((H16*I16)/1550)*(J16/1000))*(Product4!$CC$5+2))*L16)+((L16/144)*15),0)) -> 253 | U16: =Roundup(((((Product4!$BZ$5+1))*L16)+((L16/144)*10)),0) -> 9286 | V16: =V14 -> 100 | W16: =Roundup(F17*I14*M16*Sheet2!E82*Sheet2!E74,0) -> 0 | X16: =IFNA((IFS(F16=1926,LOOKUP(M16,(Price!$AA$1:$AB$300),(Price!$AC$1:$AC$300)),F16=2029,LOOKUP(M16,(Price!$AA$1:$AB$300),(Price!$AF$1:$AF$300)),F16=3001,LOOKUP(N16,(Price!$AI$2:$AJ$8),(Price!$AK$2:$AK$8)),F16=2030,LOOKUP(M16,(Price!$AA$1:$AB$300),(Price!$BE$1:$BE$300)),F16=2841,LOOKUP(M16,(Price!$AA$1:$AB$300),(Price!$BF$1:$BF$300)),F16=2840,LOOKUP(M16,(Price!$AA$1:$AB$300),(Price!$AG$1:$AG$300)))),"")*Product4!$BB$15+$AH$17+W16 -> 2000 | Y16: =IFNA(IFS(G16=1002,LOOKUP(O16,(Price!$AI$2:$AJ$8),(Price!$AL$2:$AL$8)),G16=1003,lookup(O16,(Price!$AI$2:$AJ$8),(Price!$AM$2:$AM$8)),G16=1004,lookup(O16,(Price!$AI$2:$AJ$8),(Price!$AN$2:$AN$8))),"")*Product4!$BB$15 -> 0 | Z16: =(LOOKUP(L16,(Price!$AA$2:$AB$300),(Price!$AD$2:$AD$300)))*Sheet2!Z14 -> 0 | AA16: =AA14 | AB16: =AB14 | AC16: =AC14 -> 0.03 | AD16: =ROUNDUP(((K16*AB16)+((K16*AB16)*5%))+(Max(((L16*E16)*AC16),200)+1),0) -> 201 | AE16: =ROUNDUP(V16+Z16+AA16+AB16+AC16,0) -> 101 | AF16: =K16 | AG16: =(((((P16+AE16+X16+AD16)/AF16))*(0))+((P16+AE16+X16+AD16)/AF16))+$AG$17 -> #DIV/0! | AL16: =(((((U16+AE16+X16+AD16)/AF16)*(0))+((U16+AE16+X16+AD16)/AF16)))+$AJ$17 -> #DIV/0! | AM16: =((((((Roundup((((((AL$17*AM$17)/1550)*(J16/1000))*(Product4!$CC$5+2))*L16)+((L16/144)*15),0))+AE16+X16+AD16)/AF16))*(0))+(((Roundup((((((AL$17*AM$17)/1550)*(J16/1000))*(Product4!$CC$5+2))*L16)+((L16/144)*15),0))+AE16+X16+AD16)/AF16))+$AG$17 -> #DIV/0! | AW16: =MAX((((H16*I16)*(Price!$T$2)*L16)/AF16),300/AF16) -> #DIV/0! | AX16: =MAX((((H16*I16)*(Price!$S$2)*L16)/AF16),300/AF16) -> #DIV/0! | AY16: =MAX((((H16*I16)*(Price!$S$3)*L16)/AF16),300/AF16) -> #DIV/0! | AZ16: =MAX((((H16*I16)*(Price!$V$2)*L16)/AF16),300/AF16) -> #DIV/0! | BA16: =MAX(((((H16*I16)*(Price!$W$2)*L16)/AF16)+(350/AF16)),500/AF16) -> #DIV/0! | BB16: =MAX(((((H16*I16)*(Price!$Y$7)*L16)/AF16)+(350/AF16)),2500/AF16)+AW16 -> #DIV/0! | BC16: =MAX(((((H16*I16)*(Price!$U$2)*L16)/AF16)+(350/AF16)),2500/AF16) -> #DIV/0! | BD16: =(MAX(BE16:BF16)) -> #DIV/0! | BE16: =(MAX((((((((Price!$X$2)*0.17)+(Price!$X$2))*L16)+(350))/AF16)+AW16),500/AF16)) -> #DIV/0! | BF16: =((((Price!$Y$2)+350)/AF16)+AW16) -> #DIV/0! | BG16: =IFERROR(__xludf.DUMMYFUNCTION("(SPLIT(Quotation!$D$46,""*""))"),"#VALUE!") -> #VALUE! | BI16: =(Max(((((((H16*I16)*Price!$R$7)*L16)/AF16)*0)+((((H16*I16)*Price!$R$7)*L16)/AF16)+BQ16),500/AF16)) -> #DIV/0! | BJ16: =(MAX((((BG16*2)*Price!$S$7)+(((BG16*2)*Price!$S$7)*0)+BQ16),500/AF16)) -> #VALUE! | BK16: =(MAX(((((BG16*2)+(BH16*2))*Price!$S$7)+((((BG16*2)+(BH16*2))*Price!$S$7)*0)+BQ16),500/AF16)) -> #VALUE! | BL16: =(MAX((((LOOKUP(K16,(Price!$AA$2:$AB$1199),(Price!$AE$2:$AE$1199)))+((LOOKUP(K16,(Price!$AA$2:$AB$1199),(Price!$AE$2:$AE$1199)))*0))+BQ16),500/AF16)) -> #N/A | BM16: =(MAX(((((Price!$U$7)+((Price!$U$7)*0))/K16)+BL16),500/AF16)) -> #DIV/0! | BN16: =(MAX(((((Price!$V$7)+((Price!$V$7)*0))/K16)+BL16),500/AF16)) -> #DIV/0! | BO16: =(((MAX((Roundup($BO$17*L16,0)),300))/E16)/L16) -> 0.46875 | BP16: =(((MAX((Roundup($BP$5*L16,0)),300))/E16)/L16) -> 0.46875 | BQ16: =(((MAX((($BQ$17*L16)),300))/L16)/E16) -> 0.46875 | BR16: =((((MAX((((($BI$17*$BJ$17)*Price!$S$7)*L16)),300))/E16)/L16)+((((MAX((((($BI$17*$BJ$17)*Price!$S$7)*L16)),300))/E16)/L16)*Sheet2!Z47)) -> #VALUE! | BS16: =((MAX((K16*Price!$U$12),300))/K16) -> #DIV/0! | BT16: =((MAX((K16*Price!$V$12),300))/K16) -> #DIV/0!
D17: =(ROUNDUP(((($H$14*$I$14)/1550)*($J$14/1000))*($K$14/$E$14),0)) -> 327 | F17: =ROUNDUP(H14,0) -> 18 | G17: =(H14*I14)/144 -> 3.125 | H17: =CONCATENATE(F17,ROUNDUP(I14,0)) -> 1825 | I17: =IFERROR(__xludf.DUMMYFUNCTION("SPLIT(Quotation!D46,""*"")"),"#VALUE!") -> #VALUE! | K17: =((ROUNDUP(I17,0))*(ROUNDUP(J17,0))) -> #VALUE! | L17: =IFERROR(__xludf.DUMMYFUNCTION("SPLIT(Product4!CG5,"" "")"),90.0) -> 90 | M17: =IFERROR(__xludf.DUMMYFUNCTION("""COMPUTED_VALUE"""),"GSM") -> GSM | AG17: =((((F17*I14)*Price!W12)/E14)*Product4!CF74) -> 0 | AH17: =(Product4!$CG$74*Product4!$CG$110*Product4!$BB$15) -> 1000 | AJ17: =((((F17*I14)*Price!X12)/E14)*Product4!CF74) -> 0 | AL17: =IFERROR(__xludf.DUMMYFUNCTION("iferror((SPLIT(Quotation!E45,""*"")))"),"") | AU17: =(Quotation!E50) | AV17: =(Quotation!E51) | AW17: =(Quotation!B50) | BI17: =IFERROR(__xludf.DUMMYFUNCTION("(SPLIT(Quotation!E50,""*""))"),"#VALUE!") -> #VALUE! | BO17: =((((((Product8!$Z16+Product8!$AA16)+((Product8!$Z16+Product8!$AA16)*0.2))*Price!$W7)))+((((((Product8!$Z16+Product8!$AA16)+((Product8!$Z16+Product8!$AA16)*0.2))*Price!$W7)))*0)) -> 0 | BQ17: =((((((Product8!$Z16+Product8!$AA16)+((Product8!$Z16+Product8!$AA16)*0.2))*Price!$X7)))+((((((Product8!$Z16+Product8!$AA16)+((Product8!$Z16+Product8!$AA16)*0.2))*Price!$X7)))*0)) -> 0 | BR17: =IFERROR(__xludf.DUMMYFUNCTION("(SPLIT(Quotation!E51,""*""))"),"#VALUE!") -> #VALUE!

Sheet Item
A1: Type 1 | B1: Type 2 | C1: Material | D1: AddOn | E1: AddOn 2 | F1: Printing | H1: Machine | I1: Add On | J1: Add On | K1: Die | L1: Print
A2: Offset | B2: Packaging | C2: SBS | D2: Carry Bag Single Pasting | E2: Lamination Thermal | F2: Single Colour | G2: 1 | H2: 1926 | I2: New Job | J2: Leafing | K2: Yes | L2: Normal | M2: {=UNIQUE(SORT((ALLDATA!Q2:R3000)))} -> Commercial | N2: Art Card
A3: Offset | B3: Packaging | C3: WhiteBack | D3: Carry Bag Double Pasting | E3: Lamination Normal Gloss | F3: Double Colour | G3: 2 | H3: 2029 | I3: Repeat Job | J3: Leafing | K3: N/A | L3: Normal | M3: Commercial | N3: Cashify
A4: Offset | B4: Packaging | C4: GreyBack | D4: Plain | E4: Lamination Normal Matt | F4: Four Colour | G4: 4 | H4: 2840 | I4: New Job | J4: Leafing | K4: Yes | L4: Normal | M4: Commercial | N4: Covid Kit
A5: Offset | B5: Packaging | C5: Duplex | D5: Plain | E5: Varnish | F5: Four + One Colour | G5: 6.75 | H5: 1926 | I5: Repeat Job | J5: Leafing | K5: N/A | L5: Normal | M5: Commercial | N5: Daily Essential
A6: Offset | B6: Packaging | C6: Custom Paper | D6: Plain | E6: UV Hybrid | F6: Four + Two Colour | G6: 7.75 | H6: 1926 | I6: New Job | J6: Leafing | K6: Yes | L6: Normal | M6: Commercial | N6: Dangler
A7: Offset | B7: Packaging | C7: Other Type | D7: Plain | E7: UV Flat | F7: Four + Four Colour | G7: 9.75 | H7: 1926 | I7: Repeat Job | J7: Leafing | K7: N/A | L7: Normal | M7: Commercial | N7: Envelop
A8: Offset | B8: Packaging | C8: Other Type | D8: Plain | E8: Spot UV | F8: Without Print | G8: 0 | H8: 1926 | I8: New Job | J8: Leafing | K8: Yes | L8: Normal | M8: Commercial | N8: Flyer
A9: Offset | B9: Packaging | C9: Other Type | D9: Plain | E9: UV Crystal | F9: Without Print | G9: 0 | H9: 1926 | I9: Repeat Job | J9: Leafing | K9: N/A | L9: Normal | M9: Commercial | N9: Gumming Sticker
A10: Offset | B10: Packaging | C10: Other Type | D10: Plain | E10: Plain | F10: Without Print | G10: 0 | H10: 1926 | J10: Leafing | K10: N/A | L10: Normal | M10: Commercial | N10: Hard Bound
M11: Commercial | N11: Hospital
A12: Offset | B12: Commercial | C12: Maplitho | D12: Gumming Top Bottom | E12: Lamination Thermal | F12: Single Colour | G12: 1 | H12: 1926 | I12: New Job | J12: Leafing | K12: Yes | L12: Normal | M12: Commercial | N12: Letter Head
A13: Offset | B13: Commercial | C13: Art Card | D13: Gumming 4 Sides | E13: Lamination Normal Gloss | F13: Double Colour | G13: 2 | H13: 2029 | I13: Repeat Job | J13: Leafing | K13: N/A | L13: Work and Tumble | M13: Commercial | N13: Misc
A14: Offset | B14: Commercial | C14: Custom Paper | D14: Custom Gumming | E14: Lamination Normal Matt | F14: Four Colour | G14: 4 | H14: 2840 | I14: New Job | J14: Leafing | K14: Yes | L14: Normal | M14: Commercial | N14: Mizi
A15: Offset | B15: Commercial | C15: Other Type | D15: Dangler Making | E15: Varnish | F15: Four + One Colour | G15: 6.75 | H15: 1926 | I15: Repeat Job | J15: Leafing | K15: N/A | L15: Normal | M15: Commercial | N15: Poster
A16: Offset | B16: Commercial | C16: Other Type | D16: Dangler With Rivet | E16: UV Hybrid | F16: Four + Two Colour | G16: 7.75 | H16: 1926 | I16: New Job | J16: Leafing | K16: Yes | L16: Normal | M16: Commercial | N16: Tent Card
A17: Offset | B17: Commercial | C17: Other Type | D17: Dangler With Rivet and Elastic | E17: UV Flat | F17: Four + Four Colour | G17: 9.75 | H17: 1926 | I17: Repeat Job | J17: Leafing | K17: N/A | L17: Normal | M17: Hand Made | N17: Tent Card
A18: Offset | B18: Commercial | C18: Other Type | D18: Half Cut Front | E18: Spot UV | F18: Without Print | G18: 0 | H18: 1926 | I18: New Job | J18: Leafing | K18: Yes | L18: Normal | M18: Hard Bound | N18: Hard Bound
A19: Offset | B19: Commercial | C19: Other Type | D19: Half Cut Back | E19: UV Crystal | F19: Without Print | G19: 0 | H19: 1926 | I19: Repeat Job | J19: Leafing | K19: N/A | L19: Normal | M19: Packaging | N19: Agarbatti
A20: Offset | B20: Commercial | C20: Other Type | D20: Cutting | E20: Plain | F20: Without Print | G20: 0 | H20: 1926 | I20: New Job | J20: Leafing | K20: Yes | L20: Normal | M20: Packaging | N20: Apparel
A21: Offset | B21: Commercial | C21: Other Type | D21: Carry Bag Single Pasting | E21: Plain | F21: Without Print | G21: 0 | H21: 1926 | I21: Repeat Job | J21: Leafing | K21: N/A | L21: Normal | M21: Packaging | N21: Artsbury
A22: Offset | B22: Commercial | C22: Other Type | D22: Carry Bag Double Pasting | E22: Plain | F22: Without Print | G22: 0 | H22: 1926 | I22: New Job | J22: Leafing | K22: Yes | L22: Normal | M22: Packaging | N22: Aryan
A23: Offset | B23: Commercial | C23: Other Type | D23: Plain | E23: Plain | F23: Without Print | G23: 0 | H23: 1926 | I23: Repeat Job | J23: Leafing | K23: N/A | L23: Normal | M23: Packaging | N23: Atta
M24: Packaging | N24: Bakery
M25: Packaging | N25: Bakery Online
M26: Packaging | N26: Beverages
M27: Packaging | N27: BO
M28: Packaging | N28: Boult
M29: Packaging | N29: Camera
M30: Packaging | N30: Candle
M31: Packaging | N31: Carry Bag
M32: Packaging | N32: Cerene
M33: Packaging | N33: Computer Accessories
M34: Packaging | N34: Cones
M35: Packaging | N35: Corrugation
... M82: Packaging | N82: Xpider
N83: Bakery
A96: Offset | B96: Booklet | C96: Maplitho | D96: Center Stitched | E96: Lamination Thermal | F96: Single Colour | G96: 1 | H96: 1926A | I96: New Job | J96: Leafing | K96: Yes | L96: Normal
A97: Offset | B97: Booklet | C97: Art Card | D97: Center Stappled | E97: Lamination Normal Gloss | F97: Double Colour | G97: 2 | H97: 2029A | I97: Repeat Job | J97: Leafing | K97: N/A | L97: Work and Tumble
